2022-04-06 20:09:05,614 INFO    MainThread:28088 [internal.py:wandb_internal():92] W&B internal server running at pid: 28088, started at: 2022-04-06 20:09:05.613919
2022-04-06 20:09:05,617 INFO    WriterThread:28088 [datastore.py:open_for_write():77] open: c:\Users\wasii\Documents\CodingProjects\TEMPO_Work\wandb\run-20220406_200902-3rhpz40q\run-3rhpz40q.wandb
2022-04-06 20:09:05,622 DEBUG   SenderThread:28088 [sender.py:send():235] send: header
2022-04-06 20:09:05,622 DEBUG   SenderThread:28088 [sender.py:send():235] send: run
2022-04-06 20:09:05,973 INFO    SenderThread:28088 [dir_watcher.py:__init__():169] watching files in: c:\Users\wasii\Documents\CodingProjects\TEMPO_Work\wandb\run-20220406_200902-3rhpz40q\files
2022-04-06 20:09:05,973 INFO    SenderThread:28088 [sender.py:_start_run_threads():812] run started: 3rhpz40q with start time 1649290142
2022-04-07 00:01:35,697 WARNING FileStreamThread:28088 [file_stream.py:request_with_retry():594] requests_with_retry encountered retryable exception: ('Connection aborted.', ConnectionResetError(10054, 'An existing connection was forcibly closed by the remote host', None, 10054, None)). func: <bound method Session.post of <requests.sessions.Session object at 0x000001F8E3787310>>, args: ('https://api.wandb.ai/files/wasiim/tempo_ml_training/3rhpz40q/file_stream',), kwargs: {'json': {'complete': False, 'failed': False, 'dropped': 0, 'uploaded': []}}
2022-04-07 09:43:32,143 WARNING FileStreamThread:28088 [file_stream.py:request_with_retry():594] requests_with_retry encountered retryable exception: ('Connection aborted.', TimeoutError(10060, 'A connection attempt failed because the connected party did not properly respond after a period of time, or established connection failed because connected host has failed to respond', None, 10060, None)). func: <bound method Session.post of <requests.sessions.Session object at 0x000001F8E3787310>>, args: ('https://api.wandb.ai/files/wasiim/tempo_ml_training/3rhpz40q/file_stream',), kwargs: {'json': {'complete': False, 'failed': False, 'dropped': 0, 'uploaded': []}}
2022-04-07 09:43:34,540 WARNING FileStreamThread:28088 [file_stream.py:request_with_retry():594] requests_with_retry encountered retryable exception: HTTPSConnectionPool(host='api.wandb.ai', port=443): Max retries exceeded with url: /files/wasiim/tempo_ml_training/3rhpz40q/file_stream (Caused by NewConnectionError('<urllib3.connection.HTTPSConnection object at 0x000001F8E3824C40>: Failed to establish a new connection: [Errno 11001] getaddrinfo failed')). func: <bound method Session.post of <requests.sessions.Session object at 0x000001F8E3787310>>, args: ('https://api.wandb.ai/files/wasiim/tempo_ml_training/3rhpz40q/file_stream',), kwargs: {'json': {'complete': False, 'failed': False, 'dropped': 0, 'uploaded': []}}
2022-04-07 09:43:39,340 WARNING FileStreamThread:28088 [file_stream.py:request_with_retry():594] requests_with_retry encountered retryable exception: HTTPSConnectionPool(host='api.wandb.ai', port=443): Max retries exceeded with url: /files/wasiim/tempo_ml_training/3rhpz40q/file_stream (Caused by NewConnectionError('<urllib3.connection.HTTPSConnection object at 0x000001F8E3824070>: Failed to establish a new connection: [Errno 11001] getaddrinfo failed')). func: <bound method Session.post of <requests.sessions.Session object at 0x000001F8E3787310>>, args: ('https://api.wandb.ai/files/wasiim/tempo_ml_training/3rhpz40q/file_stream',), kwargs: {'json': {'complete': False, 'failed': False, 'dropped': 0, 'uploaded': []}}
2022-04-07 09:43:48,531 WARNING FileStreamThread:28088 [file_stream.py:request_with_retry():594] requests_with_retry encountered retryable exception: HTTPSConnectionPool(host='api.wandb.ai', port=443): Max retries exceeded with url: /files/wasiim/tempo_ml_training/3rhpz40q/file_stream (Caused by NewConnectionError('<urllib3.connection.HTTPSConnection object at 0x000001F8E3824F70>: Failed to establish a new connection: [Errno 11001] getaddrinfo failed')). func: <bound method Session.post of <requests.sessions.Session object at 0x000001F8E3787310>>, args: ('https://api.wandb.ai/files/wasiim/tempo_ml_training/3rhpz40q/file_stream',), kwargs: {'json': {'complete': False, 'failed': False, 'dropped': 0, 'uploaded': []}}
2022-04-07 09:44:06,965 WARNING FileStreamThread:28088 [file_stream.py:request_with_retry():594] requests_with_retry encountered retryable exception: HTTPSConnectionPool(host='api.wandb.ai', port=443): Max retries exceeded with url: /files/wasiim/tempo_ml_training/3rhpz40q/file_stream (Caused by NewConnectionError('<urllib3.connection.HTTPSConnection object at 0x000001F8E3824AC0>: Failed to establish a new connection: [Errno 11001] getaddrinfo failed')). func: <bound method Session.post of <requests.sessions.Session object at 0x000001F8E3787310>>, args: ('https://api.wandb.ai/files/wasiim/tempo_ml_training/3rhpz40q/file_stream',), kwargs: {'json': {'complete': False, 'failed': False, 'dropped': 0, 'uploaded': []}}
2022-04-07 09:44:44,312 WARNING FileStreamThread:28088 [file_stream.py:request_with_retry():594] requests_with_retry encountered retryable exception: HTTPSConnectionPool(host='api.wandb.ai', port=443): Max retries exceeded with url: /files/wasiim/tempo_ml_training/3rhpz40q/file_stream (Caused by NewConnectionError('<urllib3.connection.HTTPSConnection object at 0x000001F8E381EFA0>: Failed to establish a new connection: [Errno 11001] getaddrinfo failed')). func: <bound method Session.post of <requests.sessions.Session object at 0x000001F8E3787310>>, args: ('https://api.wandb.ai/files/wasiim/tempo_ml_training/3rhpz40q/file_stream',), kwargs: {'json': {'complete': False, 'failed': False, 'dropped': 0, 'uploaded': []}}
2022-04-07 09:46:02,189 WARNING FileStreamThread:28088 [file_stream.py:request_with_retry():594] requests_with_retry encountered retryable exception: HTTPSConnectionPool(host='api.wandb.ai', port=443): Max retries exceeded with url: /files/wasiim/tempo_ml_training/3rhpz40q/file_stream (Caused by NewConnectionError('<urllib3.connection.HTTPSConnection object at 0x000001F8E381E1C0>: Failed to establish a new connection: [Errno 11001] getaddrinfo failed')). func: <bound method Session.post of <requests.sessions.Session object at 0x000001F8E3787310>>, args: ('https://api.wandb.ai/files/wasiim/tempo_ml_training/3rhpz40q/file_stream',), kwargs: {'json': {'complete': False, 'failed': False, 'dropped': 0, 'uploaded': []}}
2022-04-07 09:48:35,841 WARNING FileStreamThread:28088 [file_stream.py:request_with_retry():594] requests_with_retry encountered retryable exception: HTTPSConnectionPool(host='api.wandb.ai', port=443): Max retries exceeded with url: /files/wasiim/tempo_ml_training/3rhpz40q/file_stream (Caused by NewConnectionError('<urllib3.connection.HTTPSConnection object at 0x000001F8E0F8E3A0>: Failed to establish a new connection: [Errno 11001] getaddrinfo failed')). func: <bound method Session.post of <requests.sessions.Session object at 0x000001F8E3787310>>, args: ('https://api.wandb.ai/files/wasiim/tempo_ml_training/3rhpz40q/file_stream',), kwargs: {'json': {'complete': False, 'failed': False, 'dropped': 0, 'uploaded': []}}
2022-04-07 09:53:33,127 WARNING FileStreamThread:28088 [file_stream.py:request_with_retry():594] requests_with_retry encountered retryable exception: HTTPSConnectionPool(host='api.wandb.ai', port=443): Max retries exceeded with url: /files/wasiim/tempo_ml_training/3rhpz40q/file_stream (Caused by NewConnectionError('<urllib3.connection.HTTPSConnection object at 0x000001F8E0F8E9A0>: Failed to establish a new connection: [Errno 11001] getaddrinfo failed')). func: <bound method Session.post of <requests.sessions.Session object at 0x000001F8E3787310>>, args: ('https://api.wandb.ai/files/wasiim/tempo_ml_training/3rhpz40q/file_stream',), kwargs: {'json': {'complete': False, 'failed': False, 'dropped': 0, 'uploaded': []}}
2022-04-07 09:59:37,635 WARNING FileStreamThread:28088 [file_stream.py:request_with_retry():594] requests_with_retry encountered retryable exception: HTTPSConnectionPool(host='api.wandb.ai', port=443): Max retries exceeded with url: /files/wasiim/tempo_ml_training/3rhpz40q/file_stream (Caused by NewConnectionError('<urllib3.connection.HTTPSConnection object at 0x000001F8E3812CD0>: Failed to establish a new connection: [Errno 11001] getaddrinfo failed')). func: <bound method Session.post of <requests.sessions.Session object at 0x000001F8E3787310>>, args: ('https://api.wandb.ai/files/wasiim/tempo_ml_training/3rhpz40q/file_stream',), kwargs: {'json': {'complete': False, 'failed': False, 'dropped': 0, 'uploaded': []}}
2022-04-07 10:48:10,159 WARNING FileStreamThread:28088 [file_stream.py:request_with_retry():594] requests_with_retry encountered retryable exception: ('Connection aborted.', ConnectionResetError(10054, 'An existing connection was forcibly closed by the remote host', None, 10054, None)). func: <bound method Session.post of <requests.sessions.Session object at 0x000001F8E3787310>>, args: ('https://api.wandb.ai/files/wasiim/tempo_ml_training/3rhpz40q/file_stream',), kwargs: {'json': {'complete': False, 'failed': False, 'dropped': 0, 'uploaded': []}}
2022-04-07 19:46:37,872 WARNING FileStreamThread:28088 [file_stream.py:request_with_retry():594] requests_with_retry encountered retryable exception: ('Connection aborted.', ConnectionResetError(10054, 'An existing connection was forcibly closed by the remote host', None, 10054, None)). func: <bound method Session.post of <requests.sessions.Session object at 0x000001F8E3787310>>, args: ('https://api.wandb.ai/files/wasiim/tempo_ml_training/3rhpz40q/file_stream',), kwargs: {'json': {'complete': False, 'failed': False, 'dropped': 0, 'uploaded': []}}
2022-04-08 02:06:34,305 WARNING FileStreamThread:28088 [file_stream.py:request_with_retry():594] requests_with_retry encountered retryable exception: ('Connection aborted.', TimeoutError(10060, 'A connection attempt failed because the connected party did not properly respond after a period of time, or established connection failed because connected host has failed to respond', None, 10060, None)). func: <bound method Session.post of <requests.sessions.Session object at 0x000001F8E3787310>>, args: ('https://api.wandb.ai/files/wasiim/tempo_ml_training/3rhpz40q/file_stream',), kwargs: {'json': {'complete': False, 'failed': False, 'dropped': 0, 'uploaded': []}}
2022-04-08 02:06:36,343 WARNING FileStreamThread:28088 [file_stream.py:request_with_retry():594] requests_with_retry encountered retryable exception: HTTPSConnectionPool(host='api.wandb.ai', port=443): Max retries exceeded with url: /files/wasiim/tempo_ml_training/3rhpz40q/file_stream (Caused by NewConnectionError('<urllib3.connection.HTTPSConnection object at 0x000001F8E3837D00>: Failed to establish a new connection: [Errno 11001] getaddrinfo failed')). func: <bound method Session.post of <requests.sessions.Session object at 0x000001F8E3787310>>, args: ('https://api.wandb.ai/files/wasiim/tempo_ml_training/3rhpz40q/file_stream',), kwargs: {'json': {'complete': False, 'failed': False, 'dropped': 0, 'uploaded': []}}
2022-04-08 02:06:41,018 WARNING FileStreamThread:28088 [file_stream.py:request_with_retry():594] requests_with_retry encountered retryable exception: HTTPSConnectionPool(host='api.wandb.ai', port=443): Max retries exceeded with url: /files/wasiim/tempo_ml_training/3rhpz40q/file_stream (Caused by NewConnectionError('<urllib3.connection.HTTPSConnection object at 0x000001F8E3837A00>: Failed to establish a new connection: [Errno 11001] getaddrinfo failed')). func: <bound method Session.post of <requests.sessions.Session object at 0x000001F8E3787310>>, args: ('https://api.wandb.ai/files/wasiim/tempo_ml_training/3rhpz40q/file_stream',), kwargs: {'json': {'complete': False, 'failed': False, 'dropped': 0, 'uploaded': []}}
2022-04-08 02:07:01,254 WARNING FileStreamThread:28088 [file_stream.py:request_with_retry():594] requests_with_retry encountered retryable exception: HTTPSConnectionPool(host='api.wandb.ai', port=443): Max retries exceeded with url: /files/wasiim/tempo_ml_training/3rhpz40q/file_stream (Caused by NewConnectionError('<urllib3.connection.HTTPSConnection object at 0x000001F8E3837B80>: Failed to establish a new connection: [Errno 11001] getaddrinfo failed')). func: <bound method Session.post of <requests.sessions.Session object at 0x000001F8E3787310>>, args: ('https://api.wandb.ai/files/wasiim/tempo_ml_training/3rhpz40q/file_stream',), kwargs: {'json': {'complete': False, 'failed': False, 'dropped': 0, 'uploaded': []}}
2022-04-08 02:07:29,218 WARNING FileStreamThread:28088 [file_stream.py:request_with_retry():594] requests_with_retry encountered retryable exception: HTTPSConnectionPool(host='api.wandb.ai', port=443): Max retries exceeded with url: /files/wasiim/tempo_ml_training/3rhpz40q/file_stream (Caused by NewConnectionError('<urllib3.connection.HTTPSConnection object at 0x000001F8E38377C0>: Failed to establish a new connection: [Errno 11001] getaddrinfo failed')). func: <bound method Session.post of <requests.sessions.Session object at 0x000001F8E3787310>>, args: ('https://api.wandb.ai/files/wasiim/tempo_ml_training/3rhpz40q/file_stream',), kwargs: {'json': {'complete': False, 'failed': False, 'dropped': 0, 'uploaded': []}}
2022-04-08 02:08:15,760 WARNING FileStreamThread:28088 [file_stream.py:request_with_retry():594] requests_with_retry encountered retryable exception: HTTPSConnectionPool(host='api.wandb.ai', port=443): Max retries exceeded with url: /files/wasiim/tempo_ml_training/3rhpz40q/file_stream (Caused by NewConnectionError('<urllib3.connection.HTTPSConnection object at 0x000001F8E3837F40>: Failed to establish a new connection: [Errno 11001] getaddrinfo failed')). func: <bound method Session.post of <requests.sessions.Session object at 0x000001F8E3787310>>, args: ('https://api.wandb.ai/files/wasiim/tempo_ml_training/3rhpz40q/file_stream',), kwargs: {'json': {'complete': False, 'failed': False, 'dropped': 0, 'uploaded': []}}
2022-04-08 02:09:30,014 WARNING FileStreamThread:28088 [file_stream.py:request_with_retry():594] requests_with_retry encountered retryable exception: HTTPSConnectionPool(host='api.wandb.ai', port=443): Max retries exceeded with url: /files/wasiim/tempo_ml_training/3rhpz40q/file_stream (Caused by NewConnectionError('<urllib3.connection.HTTPSConnection object at 0x000001F8E382EB20>: Failed to establish a new connection: [Errno 11001] getaddrinfo failed')). func: <bound method Session.post of <requests.sessions.Session object at 0x000001F8E3787310>>, args: ('https://api.wandb.ai/files/wasiim/tempo_ml_training/3rhpz40q/file_stream',), kwargs: {'json': {'complete': False, 'failed': False, 'dropped': 0, 'uploaded': []}}
2022-04-08 10:11:59,626 WARNING FileStreamThread:28088 [file_stream.py:request_with_retry():594] requests_with_retry encountered retryable exception: ('Connection aborted.', ConnectionResetError(10054, 'An existing connection was forcibly closed by the remote host', None, 10054, None)). func: <bound method Session.post of <requests.sessions.Session object at 0x000001F8E3787310>>, args: ('https://api.wandb.ai/files/wasiim/tempo_ml_training/3rhpz40q/file_stream',), kwargs: {'json': {'complete': False, 'failed': False, 'dropped': 0, 'uploaded': []}}
2022-04-09 01:35:26,626 WARNING FileStreamThread:28088 [file_stream.py:request_with_retry():594] requests_with_retry encountered retryable exception: ('Connection aborted.', TimeoutError(10060, 'A connection attempt failed because the connected party did not properly respond after a period of time, or established connection failed because connected host has failed to respond', None, 10060, None)). func: <bound method Session.post of <requests.sessions.Session object at 0x000001F8E3787310>>, args: ('https://api.wandb.ai/files/wasiim/tempo_ml_training/3rhpz40q/file_stream',), kwargs: {'json': {'complete': False, 'failed': False, 'dropped': 0, 'uploaded': []}}
2022-04-09 01:35:49,713 WARNING FileStreamThread:28088 [file_stream.py:request_with_retry():594] requests_with_retry encountered retryable exception: HTTPSConnectionPool(host='api.wandb.ai', port=443): Max retries exceeded with url: /files/wasiim/tempo_ml_training/3rhpz40q/file_stream (Caused by NewConnectionError('<urllib3.connection.HTTPSConnection object at 0x000001F8E382B070>: Failed to establish a new connection: [WinError 10060] A connection attempt failed because the connected party did not properly respond after a period of time, or established connection failed because connected host has failed to respond')). func: <bound method Session.post of <requests.sessions.Session object at 0x000001F8E3787310>>, args: ('https://api.wandb.ai/files/wasiim/tempo_ml_training/3rhpz40q/file_stream',), kwargs: {'json': {'complete': False, 'failed': False, 'dropped': 0, 'uploaded': []}}
2022-04-09 01:36:15,002 WARNING FileStreamThread:28088 [file_stream.py:request_with_retry():594] requests_with_retry encountered retryable exception: HTTPSConnectionPool(host='api.wandb.ai', port=443): Max retries exceeded with url: /files/wasiim/tempo_ml_training/3rhpz40q/file_stream (Caused by NewConnectionError('<urllib3.connection.HTTPSConnection object at 0x000001F8E382BA00>: Failed to establish a new connection: [WinError 10060] A connection attempt failed because the connected party did not properly respond after a period of time, or established connection failed because connected host has failed to respond')). func: <bound method Session.post of <requests.sessions.Session object at 0x000001F8E3787310>>, args: ('https://api.wandb.ai/files/wasiim/tempo_ml_training/3rhpz40q/file_stream',), kwargs: {'json': {'complete': False, 'failed': False, 'dropped': 0, 'uploaded': []}}
2022-04-09 01:36:35,123 WARNING FileStreamThread:28088 [file_stream.py:request_with_retry():594] requests_with_retry encountered retryable exception: HTTPSConnectionPool(host='api.wandb.ai', port=443): Max retries exceeded with url: /files/wasiim/tempo_ml_training/3rhpz40q/file_stream (Caused by NewConnectionError('<urllib3.connection.HTTPSConnection object at 0x000001F8E382EA90>: Failed to establish a new connection: [Errno 11001] getaddrinfo failed')). func: <bound method Session.post of <requests.sessions.Session object at 0x000001F8E3787310>>, args: ('https://api.wandb.ai/files/wasiim/tempo_ml_training/3rhpz40q/file_stream',), kwargs: {'json': {'complete': False, 'failed': False, 'dropped': 0, 'uploaded': []}}
2022-04-09 01:36:52,546 WARNING FileStreamThread:28088 [file_stream.py:request_with_retry():594] requests_with_retry encountered retryable exception: HTTPSConnectionPool(host='api.wandb.ai', port=443): Max retries exceeded with url: /files/wasiim/tempo_ml_training/3rhpz40q/file_stream (Caused by NewConnectionError('<urllib3.connection.HTTPSConnection object at 0x000001F8E382EA90>: Failed to establish a new connection: [Errno 11001] getaddrinfo failed')). func: <bound method Session.post of <requests.sessions.Session object at 0x000001F8E3787310>>, args: ('https://api.wandb.ai/files/wasiim/tempo_ml_training/3rhpz40q/file_stream',), kwargs: {'json': {'complete': False, 'failed': False, 'dropped': 0, 'uploaded': []}}
2022-04-09 01:37:25,415 WARNING FileStreamThread:28088 [file_stream.py:request_with_retry():594] requests_with_retry encountered retryable exception: HTTPSConnectionPool(host='api.wandb.ai', port=443): Max retries exceeded with url: /files/wasiim/tempo_ml_training/3rhpz40q/file_stream (Caused by NewConnectionError('<urllib3.connection.HTTPSConnection object at 0x000001F8E382EA90>: Failed to establish a new connection: [Errno 11001] getaddrinfo failed')). func: <bound method Session.post of <requests.sessions.Session object at 0x000001F8E3787310>>, args: ('https://api.wandb.ai/files/wasiim/tempo_ml_training/3rhpz40q/file_stream',), kwargs: {'json': {'complete': False, 'failed': False, 'dropped': 0, 'uploaded': []}}
2022-04-09 01:38:44,684 WARNING FileStreamThread:28088 [file_stream.py:request_with_retry():594] requests_with_retry encountered retryable exception: HTTPSConnectionPool(host='api.wandb.ai', port=443): Max retries exceeded with url: /files/wasiim/tempo_ml_training/3rhpz40q/file_stream (Caused by NewConnectionError('<urllib3.connection.HTTPSConnection object at 0x000001F8E3837FA0>: Failed to establish a new connection: [Errno 11001] getaddrinfo failed')). func: <bound method Session.post of <requests.sessions.Session object at 0x000001F8E3787310>>, args: ('https://api.wandb.ai/files/wasiim/tempo_ml_training/3rhpz40q/file_stream',), kwargs: {'json': {'complete': False, 'failed': False, 'dropped': 0, 'uploaded': []}}
2022-04-09 09:23:51,409 WARNING FileStreamThread:28088 [file_stream.py:request_with_retry():594] requests_with_retry encountered retryable exception: ('Connection aborted.', TimeoutError(10060, 'A connection attempt failed because the connected party did not properly respond after a period of time, or established connection failed because connected host has failed to respond', None, 10060, None)). func: <bound method Session.post of <requests.sessions.Session object at 0x000001F8E3787310>>, args: ('https://api.wandb.ai/files/wasiim/tempo_ml_training/3rhpz40q/file_stream',), kwargs: {'json': {'complete': False, 'failed': False, 'dropped': 0, 'uploaded': []}}
2022-04-09 09:23:53,658 WARNING FileStreamThread:28088 [file_stream.py:request_with_retry():594] requests_with_retry encountered retryable exception: HTTPSConnectionPool(host='api.wandb.ai', port=443): Max retries exceeded with url: /files/wasiim/tempo_ml_training/3rhpz40q/file_stream (Caused by NewConnectionError('<urllib3.connection.HTTPSConnection object at 0x000001F8E381E070>: Failed to establish a new connection: [Errno 11001] getaddrinfo failed')). func: <bound method Session.post of <requests.sessions.Session object at 0x000001F8E3787310>>, args: ('https://api.wandb.ai/files/wasiim/tempo_ml_training/3rhpz40q/file_stream',), kwargs: {'json': {'complete': False, 'failed': False, 'dropped': 0, 'uploaded': []}}
2022-04-09 09:23:57,807 WARNING FileStreamThread:28088 [file_stream.py:request_with_retry():594] requests_with_retry encountered retryable exception: HTTPSConnectionPool(host='api.wandb.ai', port=443): Max retries exceeded with url: /files/wasiim/tempo_ml_training/3rhpz40q/file_stream (Caused by NewConnectionError('<urllib3.connection.HTTPSConnection object at 0x000001F8E381EA90>: Failed to establish a new connection: [Errno 11001] getaddrinfo failed')). func: <bound method Session.post of <requests.sessions.Session object at 0x000001F8E3787310>>, args: ('https://api.wandb.ai/files/wasiim/tempo_ml_training/3rhpz40q/file_stream',), kwargs: {'json': {'complete': False, 'failed': False, 'dropped': 0, 'uploaded': []}}
2022-04-09 09:24:05,834 WARNING FileStreamThread:28088 [file_stream.py:request_with_retry():594] requests_with_retry encountered retryable exception: HTTPSConnectionPool(host='api.wandb.ai', port=443): Max retries exceeded with url: /files/wasiim/tempo_ml_training/3rhpz40q/file_stream (Caused by NewConnectionError('<urllib3.connection.HTTPSConnection object at 0x000001F8E381EFA0>: Failed to establish a new connection: [Errno 11001] getaddrinfo failed')). func: <bound method Session.post of <requests.sessions.Session object at 0x000001F8E3787310>>, args: ('https://api.wandb.ai/files/wasiim/tempo_ml_training/3rhpz40q/file_stream',), kwargs: {'json': {'complete': False, 'failed': False, 'dropped': 0, 'uploaded': []}}
2022-04-09 09:24:23,374 WARNING FileStreamThread:28088 [file_stream.py:request_with_retry():594] requests_with_retry encountered retryable exception: HTTPSConnectionPool(host='api.wandb.ai', port=443): Max retries exceeded with url: /files/wasiim/tempo_ml_training/3rhpz40q/file_stream (Caused by NewConnectionError('<urllib3.connection.HTTPSConnection object at 0x000001F8E381EC70>: Failed to establish a new connection: [Errno 11001] getaddrinfo failed')). func: <bound method Session.post of <requests.sessions.Session object at 0x000001F8E3787310>>, args: ('https://api.wandb.ai/files/wasiim/tempo_ml_training/3rhpz40q/file_stream',), kwargs: {'json': {'complete': False, 'failed': False, 'dropped': 0, 'uploaded': []}}
2022-04-09 09:24:59,691 WARNING FileStreamThread:28088 [file_stream.py:request_with_retry():594] requests_with_retry encountered retryable exception: HTTPSConnectionPool(host='api.wandb.ai', port=443): Max retries exceeded with url: /files/wasiim/tempo_ml_training/3rhpz40q/file_stream (Caused by NewConnectionError('<urllib3.connection.HTTPSConnection object at 0x000001F8E381EA90>: Failed to establish a new connection: [Errno 11001] getaddrinfo failed')). func: <bound method Session.post of <requests.sessions.Session object at 0x000001F8E3787310>>, args: ('https://api.wandb.ai/files/wasiim/tempo_ml_training/3rhpz40q/file_stream',), kwargs: {'json': {'complete': False, 'failed': False, 'dropped': 0, 'uploaded': []}}
2022-04-09 09:26:06,819 WARNING FileStreamThread:28088 [file_stream.py:request_with_retry():594] requests_with_retry encountered retryable exception: HTTPSConnectionPool(host='api.wandb.ai', port=443): Max retries exceeded with url: /files/wasiim/tempo_ml_training/3rhpz40q/file_stream (Caused by NewConnectionError('<urllib3.connection.HTTPSConnection object at 0x000001F8E381EA60>: Failed to establish a new connection: [Errno 11001] getaddrinfo failed')). func: <bound method Session.post of <requests.sessions.Session object at 0x000001F8E3787310>>, args: ('https://api.wandb.ai/files/wasiim/tempo_ml_training/3rhpz40q/file_stream',), kwargs: {'json': {'complete': False, 'failed': False, 'dropped': 0, 'uploaded': []}}
2022-04-09 09:28:28,824 WARNING FileStreamThread:28088 [file_stream.py:request_with_retry():594] requests_with_retry encountered retryable exception: HTTPSConnectionPool(host='api.wandb.ai', port=443): Max retries exceeded with url: /files/wasiim/tempo_ml_training/3rhpz40q/file_stream (Caused by NewConnectionError('<urllib3.connection.HTTPSConnection object at 0x000001F8E381EE20>: Failed to establish a new connection: [Errno 11001] getaddrinfo failed')). func: <bound method Session.post of <requests.sessions.Session object at 0x000001F8E3787310>>, args: ('https://api.wandb.ai/files/wasiim/tempo_ml_training/3rhpz40q/file_stream',), kwargs: {'json': {'complete': False, 'failed': False, 'dropped': 0, 'uploaded': []}}
2022-04-09 09:33:22,084 WARNING FileStreamThread:28088 [file_stream.py:request_with_retry():594] requests_with_retry encountered retryable exception: HTTPSConnectionPool(host='api.wandb.ai', port=443): Max retries exceeded with url: /files/wasiim/tempo_ml_training/3rhpz40q/file_stream (Caused by NewConnectionError('<urllib3.connection.HTTPSConnection object at 0x000001F8E381E490>: Failed to establish a new connection: [Errno 11001] getaddrinfo failed')). func: <bound method Session.post of <requests.sessions.Session object at 0x000001F8E3787310>>, args: ('https://api.wandb.ai/files/wasiim/tempo_ml_training/3rhpz40q/file_stream',), kwargs: {'json': {'complete': False, 'failed': False, 'dropped': 0, 'uploaded': []}}
2022-04-09 09:38:53,241 WARNING FileStreamThread:28088 [file_stream.py:request_with_retry():594] requests_with_retry encountered retryable exception: HTTPSConnectionPool(host='api.wandb.ai', port=443): Max retries exceeded with url: /files/wasiim/tempo_ml_training/3rhpz40q/file_stream (Caused by NewConnectionError('<urllib3.connection.HTTPSConnection object at 0x000001F8E381EA60>: Failed to establish a new connection: [Errno 11001] getaddrinfo failed')). func: <bound method Session.post of <requests.sessions.Session object at 0x000001F8E3787310>>, args: ('https://api.wandb.ai/files/wasiim/tempo_ml_training/3rhpz40q/file_stream',), kwargs: {'json': {'complete': False, 'failed': False, 'dropped': 0, 'uploaded': []}}
2022-04-09 09:44:04,113 WARNING FileStreamThread:28088 [file_stream.py:request_with_retry():594] requests_with_retry encountered retryable exception: HTTPSConnectionPool(host='api.wandb.ai', port=443): Max retries exceeded with url: /files/wasiim/tempo_ml_training/3rhpz40q/file_stream (Caused by NewConnectionError('<urllib3.connection.HTTPSConnection object at 0x000001F8E381EDF0>: Failed to establish a new connection: [Errno 11001] getaddrinfo failed')). func: <bound method Session.post of <requests.sessions.Session object at 0x000001F8E3787310>>, args: ('https://api.wandb.ai/files/wasiim/tempo_ml_training/3rhpz40q/file_stream',), kwargs: {'json': {'complete': False, 'failed': False, 'dropped': 0, 'uploaded': []}}
2022-04-09 09:49:29,575 WARNING FileStreamThread:28088 [file_stream.py:request_with_retry():594] requests_with_retry encountered retryable exception: HTTPSConnectionPool(host='api.wandb.ai', port=443): Max retries exceeded with url: /files/wasiim/tempo_ml_training/3rhpz40q/file_stream (Caused by NewConnectionError('<urllib3.connection.HTTPSConnection object at 0x000001F8E3827CA0>: Failed to establish a new connection: [Errno 11001] getaddrinfo failed')). func: <bound method Session.post of <requests.sessions.Session object at 0x000001F8E3787310>>, args: ('https://api.wandb.ai/files/wasiim/tempo_ml_training/3rhpz40q/file_stream',), kwargs: {'json': {'complete': False, 'failed': False, 'dropped': 0, 'uploaded': []}}
2022-04-09 09:55:35,076 WARNING FileStreamThread:28088 [file_stream.py:request_with_retry():594] requests_with_retry encountered retryable exception: HTTPSConnectionPool(host='api.wandb.ai', port=443): Max retries exceeded with url: /files/wasiim/tempo_ml_training/3rhpz40q/file_stream (Caused by NewConnectionError('<urllib3.connection.HTTPSConnection object at 0x000001F8E38274C0>: Failed to establish a new connection: [Errno 11001] getaddrinfo failed')). func: <bound method Session.post of <requests.sessions.Session object at 0x000001F8E3787310>>, args: ('https://api.wandb.ai/files/wasiim/tempo_ml_training/3rhpz40q/file_stream',), kwargs: {'json': {'complete': False, 'failed': False, 'dropped': 0, 'uploaded': []}}
2022-04-09 10:01:08,040 WARNING FileStreamThread:28088 [file_stream.py:request_with_retry():594] requests_with_retry encountered retryable exception: HTTPSConnectionPool(host='api.wandb.ai', port=443): Max retries exceeded with url: /files/wasiim/tempo_ml_training/3rhpz40q/file_stream (Caused by NewConnectionError('<urllib3.connection.HTTPSConnection object at 0x000001F8E382ED30>: Failed to establish a new connection: [Errno 11001] getaddrinfo failed')). func: <bound method Session.post of <requests.sessions.Session object at 0x000001F8E3787310>>, args: ('https://api.wandb.ai/files/wasiim/tempo_ml_training/3rhpz40q/file_stream',), kwargs: {'json': {'complete': False, 'failed': False, 'dropped': 0, 'uploaded': []}}
2022-04-09 10:07:06,514 WARNING FileStreamThread:28088 [file_stream.py:request_with_retry():594] requests_with_retry encountered retryable exception: HTTPSConnectionPool(host='api.wandb.ai', port=443): Max retries exceeded with url: /files/wasiim/tempo_ml_training/3rhpz40q/file_stream (Caused by NewConnectionError('<urllib3.connection.HTTPSConnection object at 0x000001F8E382E4F0>: Failed to establish a new connection: [Errno 11001] getaddrinfo failed')). func: <bound method Session.post of <requests.sessions.Session object at 0x000001F8E3787310>>, args: ('https://api.wandb.ai/files/wasiim/tempo_ml_training/3rhpz40q/file_stream',), kwargs: {'json': {'complete': False, 'failed': False, 'dropped': 0, 'uploaded': []}}
2022-04-09 10:12:24,651 WARNING FileStreamThread:28088 [file_stream.py:request_with_retry():594] requests_with_retry encountered retryable exception: HTTPSConnectionPool(host='api.wandb.ai', port=443): Max retries exceeded with url: /files/wasiim/tempo_ml_training/3rhpz40q/file_stream (Caused by NewConnectionError('<urllib3.connection.HTTPSConnection object at 0x000001F8E3837310>: Failed to establish a new connection: [Errno 11001] getaddrinfo failed')). func: <bound method Session.post of <requests.sessions.Session object at 0x000001F8E3787310>>, args: ('https://api.wandb.ai/files/wasiim/tempo_ml_training/3rhpz40q/file_stream',), kwargs: {'json': {'complete': False, 'failed': False, 'dropped': 0, 'uploaded': []}}
2022-04-09 10:17:34,207 WARNING FileStreamThread:28088 [file_stream.py:request_with_retry():594] requests_with_retry encountered retryable exception: HTTPSConnectionPool(host='api.wandb.ai', port=443): Max retries exceeded with url: /files/wasiim/tempo_ml_training/3rhpz40q/file_stream (Caused by NewConnectionError('<urllib3.connection.HTTPSConnection object at 0x000001F8E3837D60>: Failed to establish a new connection: [Errno 11001] getaddrinfo failed')). func: <bound method Session.post of <requests.sessions.Session object at 0x000001F8E3787310>>, args: ('https://api.wandb.ai/files/wasiim/tempo_ml_training/3rhpz40q/file_stream',), kwargs: {'json': {'complete': False, 'failed': False, 'dropped': 0, 'uploaded': []}}
2022-04-09 10:23:47,521 WARNING FileStreamThread:28088 [file_stream.py:request_with_retry():594] requests_with_retry encountered retryable exception: HTTPSConnectionPool(host='api.wandb.ai', port=443): Max retries exceeded with url: /files/wasiim/tempo_ml_training/3rhpz40q/file_stream (Caused by NewConnectionError('<urllib3.connection.HTTPSConnection object at 0x000001F8E382ED60>: Failed to establish a new connection: [Errno 11001] getaddrinfo failed')). func: <bound method Session.post of <requests.sessions.Session object at 0x000001F8E3787310>>, args: ('https://api.wandb.ai/files/wasiim/tempo_ml_training/3rhpz40q/file_stream',), kwargs: {'json': {'complete': False, 'failed': False, 'dropped': 0, 'uploaded': []}}
2022-04-09 10:29:37,958 WARNING FileStreamThread:28088 [file_stream.py:request_with_retry():594] requests_with_retry encountered retryable exception: HTTPSConnectionPool(host='api.wandb.ai', port=443): Max retries exceeded with url: /files/wasiim/tempo_ml_training/3rhpz40q/file_stream (Caused by NewConnectionError('<urllib3.connection.HTTPSConnection object at 0x000001F8E382E760>: Failed to establish a new connection: [Errno 11001] getaddrinfo failed')). func: <bound method Session.post of <requests.sessions.Session object at 0x000001F8E3787310>>, args: ('https://api.wandb.ai/files/wasiim/tempo_ml_training/3rhpz40q/file_stream',), kwargs: {'json': {'complete': False, 'failed': False, 'dropped': 0, 'uploaded': []}}
2022-04-09 10:35:28,763 WARNING FileStreamThread:28088 [file_stream.py:request_with_retry():594] requests_with_retry encountered retryable exception: HTTPSConnectionPool(host='api.wandb.ai', port=443): Max retries exceeded with url: /files/wasiim/tempo_ml_training/3rhpz40q/file_stream (Caused by NewConnectionError('<urllib3.connection.HTTPSConnection object at 0x000001F8E377A820>: Failed to establish a new connection: [Errno 11001] getaddrinfo failed')). func: <bound method Session.post of <requests.sessions.Session object at 0x000001F8E3787310>>, args: ('https://api.wandb.ai/files/wasiim/tempo_ml_training/3rhpz40q/file_stream',), kwargs: {'json': {'complete': False, 'failed': False, 'dropped': 0, 'uploaded': []}}
2022-04-09 10:40:43,234 WARNING FileStreamThread:28088 [file_stream.py:request_with_retry():594] requests_with_retry encountered retryable exception: HTTPSConnectionPool(host='api.wandb.ai', port=443): Max retries exceeded with url: /files/wasiim/tempo_ml_training/3rhpz40q/file_stream (Caused by NewConnectionError('<urllib3.connection.HTTPSConnection object at 0x000001F8E377A3A0>: Failed to establish a new connection: [Errno 11001] getaddrinfo failed')). func: <bound method Session.post of <requests.sessions.Session object at 0x000001F8E3787310>>, args: ('https://api.wandb.ai/files/wasiim/tempo_ml_training/3rhpz40q/file_stream',), kwargs: {'json': {'complete': False, 'failed': False, 'dropped': 0, 'uploaded': []}}
2022-04-09 10:45:52,576 WARNING FileStreamThread:28088 [file_stream.py:request_with_retry():594] requests_with_retry encountered retryable exception: HTTPSConnectionPool(host='api.wandb.ai', port=443): Max retries exceeded with url: /files/wasiim/tempo_ml_training/3rhpz40q/file_stream (Caused by NewConnectionError('<urllib3.connection.HTTPSConnection object at 0x000001F8E377A820>: Failed to establish a new connection: [Errno 11001] getaddrinfo failed')). func: <bound method Session.post of <requests.sessions.Session object at 0x000001F8E3787310>>, args: ('https://api.wandb.ai/files/wasiim/tempo_ml_training/3rhpz40q/file_stream',), kwargs: {'json': {'complete': False, 'failed': False, 'dropped': 0, 'uploaded': []}}
2022-04-09 10:51:58,689 WARNING FileStreamThread:28088 [file_stream.py:request_with_retry():594] requests_with_retry encountered retryable exception: HTTPSConnectionPool(host='api.wandb.ai', port=443): Max retries exceeded with url: /files/wasiim/tempo_ml_training/3rhpz40q/file_stream (Caused by NewConnectionError('<urllib3.connection.HTTPSConnection object at 0x000001F8E3837910>: Failed to establish a new connection: [Errno 11001] getaddrinfo failed')). func: <bound method Session.post of <requests.sessions.Session object at 0x000001F8E3787310>>, args: ('https://api.wandb.ai/files/wasiim/tempo_ml_training/3rhpz40q/file_stream',), kwargs: {'json': {'complete': False, 'failed': False, 'dropped': 0, 'uploaded': []}}
2022-04-09 10:57:43,315 WARNING FileStreamThread:28088 [file_stream.py:request_with_retry():594] requests_with_retry encountered retryable exception: HTTPSConnectionPool(host='api.wandb.ai', port=443): Max retries exceeded with url: /files/wasiim/tempo_ml_training/3rhpz40q/file_stream (Caused by NewConnectionError('<urllib3.connection.HTTPSConnection object at 0x000001F8E3824520>: Failed to establish a new connection: [Errno 11001] getaddrinfo failed')). func: <bound method Session.post of <requests.sessions.Session object at 0x000001F8E3787310>>, args: ('https://api.wandb.ai/files/wasiim/tempo_ml_training/3rhpz40q/file_stream',), kwargs: {'json': {'complete': False, 'failed': False, 'dropped': 0, 'uploaded': []}}
2022-04-09 11:03:26,915 WARNING FileStreamThread:28088 [file_stream.py:request_with_retry():594] requests_with_retry encountered retryable exception: HTTPSConnectionPool(host='api.wandb.ai', port=443): Max retries exceeded with url: /files/wasiim/tempo_ml_training/3rhpz40q/file_stream (Caused by NewConnectionError('<urllib3.connection.HTTPSConnection object at 0x000001F8E3824A30>: Failed to establish a new connection: [Errno 11001] getaddrinfo failed')). func: <bound method Session.post of <requests.sessions.Session object at 0x000001F8E3787310>>, args: ('https://api.wandb.ai/files/wasiim/tempo_ml_training/3rhpz40q/file_stream',), kwargs: {'json': {'complete': False, 'failed': False, 'dropped': 0, 'uploaded': []}}
2022-04-09 11:08:44,357 WARNING FileStreamThread:28088 [file_stream.py:request_with_retry():594] requests_with_retry encountered retryable exception: HTTPSConnectionPool(host='api.wandb.ai', port=443): Max retries exceeded with url: /files/wasiim/tempo_ml_training/3rhpz40q/file_stream (Caused by NewConnectionError('<urllib3.connection.HTTPSConnection object at 0x000001F8E38245E0>: Failed to establish a new connection: [Errno 11001] getaddrinfo failed')). func: <bound method Session.post of <requests.sessions.Session object at 0x000001F8E3787310>>, args: ('https://api.wandb.ai/files/wasiim/tempo_ml_training/3rhpz40q/file_stream',), kwargs: {'json': {'complete': False, 'failed': False, 'dropped': 0, 'uploaded': []}}
2022-04-09 12:03:11,750 WARNING FileStreamThread:28088 [file_stream.py:request_with_retry():594] requests_with_retry encountered retryable exception: ('Connection aborted.', TimeoutError(10060, 'A connection attempt failed because the connected party did not properly respond after a period of time, or established connection failed because connected host has failed to respond', None, 10060, None)). func: <bound method Session.post of <requests.sessions.Session object at 0x000001F8E3787310>>, args: ('https://api.wandb.ai/files/wasiim/tempo_ml_training/3rhpz40q/file_stream',), kwargs: {'json': {'complete': False, 'failed': False, 'dropped': 0, 'uploaded': []}}
2022-04-09 12:03:25,062 WARNING FileStreamThread:28088 [file_stream.py:request_with_retry():594] requests_with_retry encountered retryable exception: HTTPSConnectionPool(host='api.wandb.ai', port=443): Max retries exceeded with url: /files/wasiim/tempo_ml_training/3rhpz40q/file_stream (Caused by NewConnectionError('<urllib3.connection.HTTPSConnection object at 0x000001F8E38362E0>: Failed to establish a new connection: [Errno 11001] getaddrinfo failed')). func: <bound method Session.post of <requests.sessions.Session object at 0x000001F8E3787310>>, args: ('https://api.wandb.ai/files/wasiim/tempo_ml_training/3rhpz40q/file_stream',), kwargs: {'json': {'complete': False, 'failed': False, 'dropped': 0, 'uploaded': []}}
2022-04-09 12:03:29,628 WARNING FileStreamThread:28088 [file_stream.py:request_with_retry():594] requests_with_retry encountered retryable exception: HTTPSConnectionPool(host='api.wandb.ai', port=443): Max retries exceeded with url: /files/wasiim/tempo_ml_training/3rhpz40q/file_stream (Caused by NewConnectionError('<urllib3.connection.HTTPSConnection object at 0x000001F8E3836CD0>: Failed to establish a new connection: [Errno 11001] getaddrinfo failed')). func: <bound method Session.post of <requests.sessions.Session object at 0x000001F8E3787310>>, args: ('https://api.wandb.ai/files/wasiim/tempo_ml_training/3rhpz40q/file_stream',), kwargs: {'json': {'complete': False, 'failed': False, 'dropped': 0, 'uploaded': []}}
2022-04-09 12:03:38,864 WARNING FileStreamThread:28088 [file_stream.py:request_with_retry():594] requests_with_retry encountered retryable exception: HTTPSConnectionPool(host='api.wandb.ai', port=443): Max retries exceeded with url: /files/wasiim/tempo_ml_training/3rhpz40q/file_stream (Caused by NewConnectionError('<urllib3.connection.HTTPSConnection object at 0x000001F8E3836E80>: Failed to establish a new connection: [Errno 11001] getaddrinfo failed')). func: <bound method Session.post of <requests.sessions.Session object at 0x000001F8E3787310>>, args: ('https://api.wandb.ai/files/wasiim/tempo_ml_training/3rhpz40q/file_stream',), kwargs: {'json': {'complete': False, 'failed': False, 'dropped': 0, 'uploaded': []}}
2022-04-09 12:03:56,140 WARNING FileStreamThread:28088 [file_stream.py:request_with_retry():594] requests_with_retry encountered retryable exception: HTTPSConnectionPool(host='api.wandb.ai', port=443): Max retries exceeded with url: /files/wasiim/tempo_ml_training/3rhpz40q/file_stream (Caused by NewConnectionError('<urllib3.connection.HTTPSConnection object at 0x000001F8E3836B50>: Failed to establish a new connection: [Errno 11001] getaddrinfo failed')). func: <bound method Session.post of <requests.sessions.Session object at 0x000001F8E3787310>>, args: ('https://api.wandb.ai/files/wasiim/tempo_ml_training/3rhpz40q/file_stream',), kwargs: {'json': {'complete': False, 'failed': False, 'dropped': 0, 'uploaded': []}}
2022-04-09 12:04:32,343 WARNING FileStreamThread:28088 [file_stream.py:request_with_retry():594] requests_with_retry encountered retryable exception: HTTPSConnectionPool(host='api.wandb.ai', port=443): Max retries exceeded with url: /files/wasiim/tempo_ml_training/3rhpz40q/file_stream (Caused by NewConnectionError('<urllib3.connection.HTTPSConnection object at 0x000001F8E3836F10>: Failed to establish a new connection: [Errno 11001] getaddrinfo failed')). func: <bound method Session.post of <requests.sessions.Session object at 0x000001F8E3787310>>, args: ('https://api.wandb.ai/files/wasiim/tempo_ml_training/3rhpz40q/file_stream',), kwargs: {'json': {'complete': False, 'failed': False, 'dropped': 0, 'uploaded': []}}
2022-04-09 12:05:36,921 WARNING FileStreamThread:28088 [file_stream.py:request_with_retry():594] requests_with_retry encountered retryable exception: HTTPSConnectionPool(host='api.wandb.ai', port=443): Max retries exceeded with url: /files/wasiim/tempo_ml_training/3rhpz40q/file_stream (Caused by NewConnectionError('<urllib3.connection.HTTPSConnection object at 0x000001F8E38363A0>: Failed to establish a new connection: [Errno 11001] getaddrinfo failed')). func: <bound method Session.post of <requests.sessions.Session object at 0x000001F8E3787310>>, args: ('https://api.wandb.ai/files/wasiim/tempo_ml_training/3rhpz40q/file_stream',), kwargs: {'json': {'complete': False, 'failed': False, 'dropped': 0, 'uploaded': []}}
2022-04-09 12:07:53,189 WARNING FileStreamThread:28088 [file_stream.py:request_with_retry():594] requests_with_retry encountered retryable exception: HTTPSConnectionPool(host='api.wandb.ai', port=443): Max retries exceeded with url: /files/wasiim/tempo_ml_training/3rhpz40q/file_stream (Caused by NewConnectionError('<urllib3.connection.HTTPSConnection object at 0x000001F8E3836970>: Failed to establish a new connection: [Errno 11001] getaddrinfo failed')). func: <bound method Session.post of <requests.sessions.Session object at 0x000001F8E3787310>>, args: ('https://api.wandb.ai/files/wasiim/tempo_ml_training/3rhpz40q/file_stream',), kwargs: {'json': {'complete': False, 'failed': False, 'dropped': 0, 'uploaded': []}}
2022-04-09 12:12:52,768 WARNING FileStreamThread:28088 [file_stream.py:request_with_retry():594] requests_with_retry encountered retryable exception: HTTPSConnectionPool(host='api.wandb.ai', port=443): Max retries exceeded with url: /files/wasiim/tempo_ml_training/3rhpz40q/file_stream (Caused by NewConnectionError('<urllib3.connection.HTTPSConnection object at 0x000001F8E3836EB0>: Failed to establish a new connection: [Errno 11001] getaddrinfo failed')). func: <bound method Session.post of <requests.sessions.Session object at 0x000001F8E3787310>>, args: ('https://api.wandb.ai/files/wasiim/tempo_ml_training/3rhpz40q/file_stream',), kwargs: {'json': {'complete': False, 'failed': False, 'dropped': 0, 'uploaded': []}}
2022-04-09 12:18:02,193 WARNING FileStreamThread:28088 [file_stream.py:request_with_retry():594] requests_with_retry encountered retryable exception: HTTPSConnectionPool(host='api.wandb.ai', port=443): Max retries exceeded with url: /files/wasiim/tempo_ml_training/3rhpz40q/file_stream (Caused by NewConnectionError('<urllib3.connection.HTTPSConnection object at 0x000001F8E3836CD0>: Failed to establish a new connection: [Errno 11001] getaddrinfo failed')). func: <bound method Session.post of <requests.sessions.Session object at 0x000001F8E3787310>>, args: ('https://api.wandb.ai/files/wasiim/tempo_ml_training/3rhpz40q/file_stream',), kwargs: {'json': {'complete': False, 'failed': False, 'dropped': 0, 'uploaded': []}}
2022-04-09 12:23:31,783 WARNING FileStreamThread:28088 [file_stream.py:request_with_retry():594] requests_with_retry encountered retryable exception: HTTPSConnectionPool(host='api.wandb.ai', port=443): Max retries exceeded with url: /files/wasiim/tempo_ml_training/3rhpz40q/file_stream (Caused by NewConnectionError('<urllib3.connection.HTTPSConnection object at 0x000001F8E3836970>: Failed to establish a new connection: [Errno 11001] getaddrinfo failed')). func: <bound method Session.post of <requests.sessions.Session object at 0x000001F8E3787310>>, args: ('https://api.wandb.ai/files/wasiim/tempo_ml_training/3rhpz40q/file_stream',), kwargs: {'json': {'complete': False, 'failed': False, 'dropped': 0, 'uploaded': []}}
2022-04-09 14:31:10,953 WARNING FileStreamThread:28088 [file_stream.py:request_with_retry():594] requests_with_retry encountered retryable exception: ('Connection aborted.', TimeoutError(10060, 'A connection attempt failed because the connected party did not properly respond after a period of time, or established connection failed because connected host has failed to respond', None, 10060, None)). func: <bound method Session.post of <requests.sessions.Session object at 0x000001F8E3787310>>, args: ('https://api.wandb.ai/files/wasiim/tempo_ml_training/3rhpz40q/file_stream',), kwargs: {'json': {'complete': False, 'failed': False, 'dropped': 0, 'uploaded': []}}
2022-04-09 14:31:13,167 WARNING FileStreamThread:28088 [file_stream.py:request_with_retry():594] requests_with_retry encountered retryable exception: HTTPSConnectionPool(host='api.wandb.ai', port=443): Max retries exceeded with url: /files/wasiim/tempo_ml_training/3rhpz40q/file_stream (Caused by NewConnectionError('<urllib3.connection.HTTPSConnection object at 0x000001F8E3837790>: Failed to establish a new connection: [Errno 11001] getaddrinfo failed')). func: <bound method Session.post of <requests.sessions.Session object at 0x000001F8E3787310>>, args: ('https://api.wandb.ai/files/wasiim/tempo_ml_training/3rhpz40q/file_stream',), kwargs: {'json': {'complete': False, 'failed': False, 'dropped': 0, 'uploaded': []}}
2022-04-09 14:31:17,658 WARNING FileStreamThread:28088 [file_stream.py:request_with_retry():594] requests_with_retry encountered retryable exception: HTTPSConnectionPool(host='api.wandb.ai', port=443): Max retries exceeded with url: /files/wasiim/tempo_ml_training/3rhpz40q/file_stream (Caused by NewConnectionError('<urllib3.connection.HTTPSConnection object at 0x000001F8E38370D0>: Failed to establish a new connection: [Errno 11001] getaddrinfo failed')). func: <bound method Session.post of <requests.sessions.Session object at 0x000001F8E3787310>>, args: ('https://api.wandb.ai/files/wasiim/tempo_ml_training/3rhpz40q/file_stream',), kwargs: {'json': {'complete': False, 'failed': False, 'dropped': 0, 'uploaded': []}}
2022-04-09 14:31:26,035 WARNING FileStreamThread:28088 [file_stream.py:request_with_retry():594] requests_with_retry encountered retryable exception: HTTPSConnectionPool(host='api.wandb.ai', port=443): Max retries exceeded with url: /files/wasiim/tempo_ml_training/3rhpz40q/file_stream (Caused by NewConnectionError('<urllib3.connection.HTTPSConnection object at 0x000001F8E3837640>: Failed to establish a new connection: [Errno 11001] getaddrinfo failed')). func: <bound method Session.post of <requests.sessions.Session object at 0x000001F8E3787310>>, args: ('https://api.wandb.ai/files/wasiim/tempo_ml_training/3rhpz40q/file_stream',), kwargs: {'json': {'complete': False, 'failed': False, 'dropped': 0, 'uploaded': []}}
2022-04-09 14:31:45,055 WARNING FileStreamThread:28088 [file_stream.py:request_with_retry():594] requests_with_retry encountered retryable exception: HTTPSConnectionPool(host='api.wandb.ai', port=443): Max retries exceeded with url: /files/wasiim/tempo_ml_training/3rhpz40q/file_stream (Caused by NewConnectionError('<urllib3.connection.HTTPSConnection object at 0x000001F8E3837C10>: Failed to establish a new connection: [Errno 11001] getaddrinfo failed')). func: <bound method Session.post of <requests.sessions.Session object at 0x000001F8E3787310>>, args: ('https://api.wandb.ai/files/wasiim/tempo_ml_training/3rhpz40q/file_stream',), kwargs: {'json': {'complete': False, 'failed': False, 'dropped': 0, 'uploaded': []}}
2022-04-09 14:32:21,450 WARNING FileStreamThread:28088 [file_stream.py:request_with_retry():594] requests_with_retry encountered retryable exception: HTTPSConnectionPool(host='api.wandb.ai', port=443): Max retries exceeded with url: /files/wasiim/tempo_ml_training/3rhpz40q/file_stream (Caused by NewConnectionError('<urllib3.connection.HTTPSConnection object at 0x000001F8E3837E50>: Failed to establish a new connection: [Errno 11001] getaddrinfo failed')). func: <bound method Session.post of <requests.sessions.Session object at 0x000001F8E3787310>>, args: ('https://api.wandb.ai/files/wasiim/tempo_ml_training/3rhpz40q/file_stream',), kwargs: {'json': {'complete': False, 'failed': False, 'dropped': 0, 'uploaded': []}}
2022-04-09 14:33:25,545 WARNING FileStreamThread:28088 [file_stream.py:request_with_retry():594] requests_with_retry encountered retryable exception: HTTPSConnectionPool(host='api.wandb.ai', port=443): Max retries exceeded with url: /files/wasiim/tempo_ml_training/3rhpz40q/file_stream (Caused by NewConnectionError('<urllib3.connection.HTTPSConnection object at 0x000001F8E3837F40>: Failed to establish a new connection: [Errno 11001] getaddrinfo failed')). func: <bound method Session.post of <requests.sessions.Session object at 0x000001F8E3787310>>, args: ('https://api.wandb.ai/files/wasiim/tempo_ml_training/3rhpz40q/file_stream',), kwargs: {'json': {'complete': False, 'failed': False, 'dropped': 0, 'uploaded': []}}
2022-04-09 16:28:42,664 WARNING FileStreamThread:28088 [file_stream.py:request_with_retry():594] requests_with_retry encountered retryable exception: ('Connection aborted.', TimeoutError(10060, 'A connection attempt failed because the connected party did not properly respond after a period of time, or established connection failed because connected host has failed to respond', None, 10060, None)). func: <bound method Session.post of <requests.sessions.Session object at 0x000001F8E3787310>>, args: ('https://api.wandb.ai/files/wasiim/tempo_ml_training/3rhpz40q/file_stream',), kwargs: {'json': {'complete': False, 'failed': False, 'dropped': 0, 'uploaded': []}}
2022-04-09 16:28:56,092 WARNING FileStreamThread:28088 [file_stream.py:request_with_retry():594] requests_with_retry encountered retryable exception: HTTPSConnectionPool(host='api.wandb.ai', port=443): Max retries exceeded with url: /files/wasiim/tempo_ml_training/3rhpz40q/file_stream (Caused by NewConnectionError('<urllib3.connection.HTTPSConnection object at 0x000001F8E3836D30>: Failed to establish a new connection: [Errno 11001] getaddrinfo failed')). func: <bound method Session.post of <requests.sessions.Session object at 0x000001F8E3787310>>, args: ('https://api.wandb.ai/files/wasiim/tempo_ml_training/3rhpz40q/file_stream',), kwargs: {'json': {'complete': False, 'failed': False, 'dropped': 0, 'uploaded': []}}
2022-04-09 16:29:11,908 WARNING FileStreamThread:28088 [file_stream.py:request_with_retry():594] requests_with_retry encountered retryable exception: HTTPSConnectionPool(host='api.wandb.ai', port=443): Max retries exceeded with url: /files/wasiim/tempo_ml_training/3rhpz40q/file_stream (Caused by NewConnectionError('<urllib3.connection.HTTPSConnection object at 0x000001F8E38368B0>: Failed to establish a new connection: [Errno 11001] getaddrinfo failed')). func: <bound method Session.post of <requests.sessions.Session object at 0x000001F8E3787310>>, args: ('https://api.wandb.ai/files/wasiim/tempo_ml_training/3rhpz40q/file_stream',), kwargs: {'json': {'complete': False, 'failed': False, 'dropped': 0, 'uploaded': []}}
2022-04-09 16:29:31,150 WARNING FileStreamThread:28088 [file_stream.py:request_with_retry():594] requests_with_retry encountered retryable exception: HTTPSConnectionPool(host='api.wandb.ai', port=443): Max retries exceeded with url: /files/wasiim/tempo_ml_training/3rhpz40q/file_stream (Caused by NewConnectionError('<urllib3.connection.HTTPSConnection object at 0x000001F8E3836D30>: Failed to establish a new connection: [Errno 11001] getaddrinfo failed')). func: <bound method Session.post of <requests.sessions.Session object at 0x000001F8E3787310>>, args: ('https://api.wandb.ai/files/wasiim/tempo_ml_training/3rhpz40q/file_stream',), kwargs: {'json': {'complete': False, 'failed': False, 'dropped': 0, 'uploaded': []}}
2022-04-09 16:29:59,788 WARNING FileStreamThread:28088 [file_stream.py:request_with_retry():594] requests_with_retry encountered retryable exception: HTTPSConnectionPool(host='api.wandb.ai', port=443): Max retries exceeded with url: /files/wasiim/tempo_ml_training/3rhpz40q/file_stream (Caused by NewConnectionError('<urllib3.connection.HTTPSConnection object at 0x000001F8E38362B0>: Failed to establish a new connection: [Errno 11001] getaddrinfo failed')). func: <bound method Session.post of <requests.sessions.Session object at 0x000001F8E3787310>>, args: ('https://api.wandb.ai/files/wasiim/tempo_ml_training/3rhpz40q/file_stream',), kwargs: {'json': {'complete': False, 'failed': False, 'dropped': 0, 'uploaded': []}}
2022-04-09 16:30:38,786 WARNING FileStreamThread:28088 [file_stream.py:request_with_retry():594] requests_with_retry encountered retryable exception: HTTPSConnectionPool(host='api.wandb.ai', port=443): Max retries exceeded with url: /files/wasiim/tempo_ml_training/3rhpz40q/file_stream (Caused by NewConnectionError('<urllib3.connection.HTTPSConnection object at 0x000001F8E38279A0>: Failed to establish a new connection: [Errno 11001] getaddrinfo failed')). func: <bound method Session.post of <requests.sessions.Session object at 0x000001F8E3787310>>, args: ('https://api.wandb.ai/files/wasiim/tempo_ml_training/3rhpz40q/file_stream',), kwargs: {'json': {'complete': False, 'failed': False, 'dropped': 0, 'uploaded': []}}
2022-04-09 16:31:43,908 WARNING FileStreamThread:28088 [file_stream.py:request_with_retry():594] requests_with_retry encountered retryable exception: HTTPSConnectionPool(host='api.wandb.ai', port=443): Max retries exceeded with url: /files/wasiim/tempo_ml_training/3rhpz40q/file_stream (Caused by NewConnectionError('<urllib3.connection.HTTPSConnection object at 0x000001F8E382E460>: Failed to establish a new connection: [Errno 11001] getaddrinfo failed')). func: <bound method Session.post of <requests.sessions.Session object at 0x000001F8E3787310>>, args: ('https://api.wandb.ai/files/wasiim/tempo_ml_training/3rhpz40q/file_stream',), kwargs: {'json': {'complete': False, 'failed': False, 'dropped': 0, 'uploaded': []}}
2022-04-09 16:34:13,568 WARNING FileStreamThread:28088 [file_stream.py:request_with_retry():594] requests_with_retry encountered retryable exception: HTTPSConnectionPool(host='api.wandb.ai', port=443): Max retries exceeded with url: /files/wasiim/tempo_ml_training/3rhpz40q/file_stream (Caused by NewConnectionError('<urllib3.connection.HTTPSConnection object at 0x000001F8E382E5E0>: Failed to establish a new connection: [Errno 11001] getaddrinfo failed')). func: <bound method Session.post of <requests.sessions.Session object at 0x000001F8E3787310>>, args: ('https://api.wandb.ai/files/wasiim/tempo_ml_training/3rhpz40q/file_stream',), kwargs: {'json': {'complete': False, 'failed': False, 'dropped': 0, 'uploaded': []}}
2022-04-09 19:07:02,589 WARNING FileStreamThread:28088 [file_stream.py:request_with_retry():594] requests_with_retry encountered retryable exception: ('Connection aborted.', TimeoutError(10060, 'A connection attempt failed because the connected party did not properly respond after a period of time, or established connection failed because connected host has failed to respond', None, 10060, None)). func: <bound method Session.post of <requests.sessions.Session object at 0x000001F8E3787310>>, args: ('https://api.wandb.ai/files/wasiim/tempo_ml_training/3rhpz40q/file_stream',), kwargs: {'json': {'complete': False, 'failed': False, 'dropped': 0, 'uploaded': []}}
2022-04-09 19:07:15,748 WARNING FileStreamThread:28088 [file_stream.py:request_with_retry():594] requests_with_retry encountered retryable exception: HTTPSConnectionPool(host='api.wandb.ai', port=443): Max retries exceeded with url: /files/wasiim/tempo_ml_training/3rhpz40q/file_stream (Caused by NewConnectionError('<urllib3.connection.HTTPSConnection object at 0x000001F8E3836640>: Failed to establish a new connection: [Errno 11001] getaddrinfo failed')). func: <bound method Session.post of <requests.sessions.Session object at 0x000001F8E3787310>>, args: ('https://api.wandb.ai/files/wasiim/tempo_ml_training/3rhpz40q/file_stream',), kwargs: {'json': {'complete': False, 'failed': False, 'dropped': 0, 'uploaded': []}}
2022-04-09 19:07:20,009 WARNING FileStreamThread:28088 [file_stream.py:request_with_retry():594] requests_with_retry encountered retryable exception: HTTPSConnectionPool(host='api.wandb.ai', port=443): Max retries exceeded with url: /files/wasiim/tempo_ml_training/3rhpz40q/file_stream (Caused by NewConnectionError('<urllib3.connection.HTTPSConnection object at 0x000001F8E3836790>: Failed to establish a new connection: [Errno 11001] getaddrinfo failed')). func: <bound method Session.post of <requests.sessions.Session object at 0x000001F8E3787310>>, args: ('https://api.wandb.ai/files/wasiim/tempo_ml_training/3rhpz40q/file_stream',), kwargs: {'json': {'complete': False, 'failed': False, 'dropped': 0, 'uploaded': []}}
2022-04-09 19:07:28,178 WARNING FileStreamThread:28088 [file_stream.py:request_with_retry():594] requests_with_retry encountered retryable exception: HTTPSConnectionPool(host='api.wandb.ai', port=443): Max retries exceeded with url: /files/wasiim/tempo_ml_training/3rhpz40q/file_stream (Caused by NewConnectionError('<urllib3.connection.HTTPSConnection object at 0x000001F8E38362B0>: Failed to establish a new connection: [Errno 11001] getaddrinfo failed')). func: <bound method Session.post of <requests.sessions.Session object at 0x000001F8E3787310>>, args: ('https://api.wandb.ai/files/wasiim/tempo_ml_training/3rhpz40q/file_stream',), kwargs: {'json': {'complete': False, 'failed': False, 'dropped': 0, 'uploaded': []}}
2022-04-09 19:07:59,880 WARNING FileStreamThread:28088 [file_stream.py:request_with_retry():594] requests_with_retry encountered retryable exception: HTTPSConnectionPool(host='api.wandb.ai', port=443): Max retries exceeded with url: /files/wasiim/tempo_ml_training/3rhpz40q/file_stream (Caused by NewConnectionError('<urllib3.connection.HTTPSConnection object at 0x000001F8E38366D0>: Failed to establish a new connection: [Errno 11001] getaddrinfo failed')). func: <bound method Session.post of <requests.sessions.Session object at 0x000001F8E3787310>>, args: ('https://api.wandb.ai/files/wasiim/tempo_ml_training/3rhpz40q/file_stream',), kwargs: {'json': {'complete': False, 'failed': False, 'dropped': 0, 'uploaded': []}}
2022-04-09 19:08:36,849 WARNING FileStreamThread:28088 [file_stream.py:request_with_retry():594] requests_with_retry encountered retryable exception: HTTPSConnectionPool(host='api.wandb.ai', port=443): Max retries exceeded with url: /files/wasiim/tempo_ml_training/3rhpz40q/file_stream (Caused by NewConnectionError('<urllib3.connection.HTTPSConnection object at 0x000001F8E381ECD0>: Failed to establish a new connection: [Errno 11001] getaddrinfo failed')). func: <bound method Session.post of <requests.sessions.Session object at 0x000001F8E3787310>>, args: ('https://api.wandb.ai/files/wasiim/tempo_ml_training/3rhpz40q/file_stream',), kwargs: {'json': {'complete': False, 'failed': False, 'dropped': 0, 'uploaded': []}}
2022-04-09 19:10:26,765 WARNING FileStreamThread:28088 [file_stream.py:request_with_retry():594] requests_with_retry encountered retryable exception: HTTPSConnectionPool(host='api.wandb.ai', port=443): Max retries exceeded with url: /files/wasiim/tempo_ml_training/3rhpz40q/file_stream (Caused by NewConnectionError('<urllib3.connection.HTTPSConnection object at 0x000001F8E381E280>: Failed to establish a new connection: [Errno 11001] getaddrinfo failed')). func: <bound method Session.post of <requests.sessions.Session object at 0x000001F8E3787310>>, args: ('https://api.wandb.ai/files/wasiim/tempo_ml_training/3rhpz40q/file_stream',), kwargs: {'json': {'complete': False, 'failed': False, 'dropped': 0, 'uploaded': []}}
2022-04-09 19:10:29,000 WARNING FileStreamThread:28088 [file_stream.py:request_with_retry():594] requests_with_retry encountered retryable exception: HTTPSConnectionPool(host='api.wandb.ai', port=443): Max retries exceeded with url: /files/wasiim/tempo_ml_training/3rhpz40q/file_stream (Caused by NewConnectionError('<urllib3.connection.HTTPSConnection object at 0x000001F8E3824880>: Failed to establish a new connection: [Errno 11001] getaddrinfo failed')). func: <bound method Session.post of <requests.sessions.Session object at 0x000001F8E3787310>>, args: ('https://api.wandb.ai/files/wasiim/tempo_ml_training/3rhpz40q/file_stream',), kwargs: {'json': {'complete': False, 'failed': False, 'dropped': 0, 'uploaded': []}}
2022-04-09 19:10:33,906 WARNING FileStreamThread:28088 [file_stream.py:request_with_retry():594] requests_with_retry encountered retryable exception: HTTPSConnectionPool(host='api.wandb.ai', port=443): Max retries exceeded with url: /files/wasiim/tempo_ml_training/3rhpz40q/file_stream (Caused by NewConnectionError('<urllib3.connection.HTTPSConnection object at 0x000001F8E38245B0>: Failed to establish a new connection: [Errno 11001] getaddrinfo failed')). func: <bound method Session.post of <requests.sessions.Session object at 0x000001F8E3787310>>, args: ('https://api.wandb.ai/files/wasiim/tempo_ml_training/3rhpz40q/file_stream',), kwargs: {'json': {'complete': False, 'failed': False, 'dropped': 0, 'uploaded': []}}
2022-04-10 12:23:41,087 WARNING FileStreamThread:28088 [file_stream.py:request_with_retry():594] requests_with_retry encountered retryable exception: ('Connection aborted.', TimeoutError(10060, 'A connection attempt failed because the connected party did not properly respond after a period of time, or established connection failed because connected host has failed to respond', None, 10060, None)). func: <bound method Session.post of <requests.sessions.Session object at 0x000001F8E3787310>>, args: ('https://api.wandb.ai/files/wasiim/tempo_ml_training/3rhpz40q/file_stream',), kwargs: {'json': {'complete': False, 'failed': False, 'dropped': 0, 'uploaded': []}}
2022-04-10 12:23:54,566 WARNING FileStreamThread:28088 [file_stream.py:request_with_retry():594] requests_with_retry encountered retryable exception: HTTPSConnectionPool(host='api.wandb.ai', port=443): Max retries exceeded with url: /files/wasiim/tempo_ml_training/3rhpz40q/file_stream (Caused by NewConnectionError('<urllib3.connection.HTTPSConnection object at 0x000001F8E3837820>: Failed to establish a new connection: [Errno 11001] getaddrinfo failed')). func: <bound method Session.post of <requests.sessions.Session object at 0x000001F8E3787310>>, args: ('https://api.wandb.ai/files/wasiim/tempo_ml_training/3rhpz40q/file_stream',), kwargs: {'json': {'complete': False, 'failed': False, 'dropped': 0, 'uploaded': []}}
2022-04-10 12:24:10,439 WARNING FileStreamThread:28088 [file_stream.py:request_with_retry():594] requests_with_retry encountered retryable exception: HTTPSConnectionPool(host='api.wandb.ai', port=443): Max retries exceeded with url: /files/wasiim/tempo_ml_training/3rhpz40q/file_stream (Caused by NewConnectionError('<urllib3.connection.HTTPSConnection object at 0x000001F8E38376A0>: Failed to establish a new connection: [Errno 11001] getaddrinfo failed')). func: <bound method Session.post of <requests.sessions.Session object at 0x000001F8E3787310>>, args: ('https://api.wandb.ai/files/wasiim/tempo_ml_training/3rhpz40q/file_stream',), kwargs: {'json': {'complete': False, 'failed': False, 'dropped': 0, 'uploaded': []}}
2022-04-10 12:24:30,021 WARNING FileStreamThread:28088 [file_stream.py:request_with_retry():594] requests_with_retry encountered retryable exception: HTTPSConnectionPool(host='api.wandb.ai', port=443): Max retries exceeded with url: /files/wasiim/tempo_ml_training/3rhpz40q/file_stream (Caused by NewConnectionError('<urllib3.connection.HTTPSConnection object at 0x000001F8E3837AF0>: Failed to establish a new connection: [Errno 11001] getaddrinfo failed')). func: <bound method Session.post of <requests.sessions.Session object at 0x000001F8E3787310>>, args: ('https://api.wandb.ai/files/wasiim/tempo_ml_training/3rhpz40q/file_stream',), kwargs: {'json': {'complete': False, 'failed': False, 'dropped': 0, 'uploaded': []}}
2022-04-10 12:24:49,301 WARNING FileStreamThread:28088 [file_stream.py:request_with_retry():594] requests_with_retry encountered retryable exception: HTTPSConnectionPool(host='api.wandb.ai', port=443): Max retries exceeded with url: /files/wasiim/tempo_ml_training/3rhpz40q/file_stream (Caused by NewConnectionError('<urllib3.connection.HTTPSConnection object at 0x000001F8E382E310>: Failed to establish a new connection: [Errno 11001] getaddrinfo failed')). func: <bound method Session.post of <requests.sessions.Session object at 0x000001F8E3787310>>, args: ('https://api.wandb.ai/files/wasiim/tempo_ml_training/3rhpz40q/file_stream',), kwargs: {'json': {'complete': False, 'failed': False, 'dropped': 0, 'uploaded': []}}
2022-04-10 12:25:25,328 WARNING FileStreamThread:28088 [file_stream.py:request_with_retry():594] requests_with_retry encountered retryable exception: HTTPSConnectionPool(host='api.wandb.ai', port=443): Max retries exceeded with url: /files/wasiim/tempo_ml_training/3rhpz40q/file_stream (Caused by NewConnectionError('<urllib3.connection.HTTPSConnection object at 0x000001F8E381E1C0>: Failed to establish a new connection: [Errno 11001] getaddrinfo failed')). func: <bound method Session.post of <requests.sessions.Session object at 0x000001F8E3787310>>, args: ('https://api.wandb.ai/files/wasiim/tempo_ml_training/3rhpz40q/file_stream',), kwargs: {'json': {'complete': False, 'failed': False, 'dropped': 0, 'uploaded': []}}
2022-04-10 14:06:05,795 WARNING FileStreamThread:28088 [file_stream.py:request_with_retry():594] requests_with_retry encountered retryable exception: ('Connection aborted.', TimeoutError(10060, 'A connection attempt failed because the connected party did not properly respond after a period of time, or established connection failed because connected host has failed to respond', None, 10060, None)). func: <bound method Session.post of <requests.sessions.Session object at 0x000001F8E3787310>>, args: ('https://api.wandb.ai/files/wasiim/tempo_ml_training/3rhpz40q/file_stream',), kwargs: {'json': {'complete': False, 'failed': False, 'dropped': 0, 'uploaded': []}}
2022-04-10 14:06:19,108 WARNING FileStreamThread:28088 [file_stream.py:request_with_retry():594] requests_with_retry encountered retryable exception: HTTPSConnectionPool(host='api.wandb.ai', port=443): Max retries exceeded with url: /files/wasiim/tempo_ml_training/3rhpz40q/file_stream (Caused by NewConnectionError('<urllib3.connection.HTTPSConnection object at 0x000001F8E38379A0>: Failed to establish a new connection: [Errno 11001] getaddrinfo failed')). func: <bound method Session.post of <requests.sessions.Session object at 0x000001F8E3787310>>, args: ('https://api.wandb.ai/files/wasiim/tempo_ml_training/3rhpz40q/file_stream',), kwargs: {'json': {'complete': False, 'failed': False, 'dropped': 0, 'uploaded': []}}
2022-04-10 14:06:35,268 WARNING FileStreamThread:28088 [file_stream.py:request_with_retry():594] requests_with_retry encountered retryable exception: HTTPSConnectionPool(host='api.wandb.ai', port=443): Max retries exceeded with url: /files/wasiim/tempo_ml_training/3rhpz40q/file_stream (Caused by NewConnectionError('<urllib3.connection.HTTPSConnection object at 0x000001F8E3837EB0>: Failed to establish a new connection: [Errno 11001] getaddrinfo failed')). func: <bound method Session.post of <requests.sessions.Session object at 0x000001F8E3787310>>, args: ('https://api.wandb.ai/files/wasiim/tempo_ml_training/3rhpz40q/file_stream',), kwargs: {'json': {'complete': False, 'failed': False, 'dropped': 0, 'uploaded': []}}
2022-04-10 14:06:56,593 WARNING FileStreamThread:28088 [file_stream.py:request_with_retry():594] requests_with_retry encountered retryable exception: HTTPSConnectionPool(host='api.wandb.ai', port=443): Max retries exceeded with url: /files/wasiim/tempo_ml_training/3rhpz40q/file_stream (Caused by NewConnectionError('<urllib3.connection.HTTPSConnection object at 0x000001F8E38248E0>: Failed to establish a new connection: [Errno 11001] getaddrinfo failed')). func: <bound method Session.post of <requests.sessions.Session object at 0x000001F8E3787310>>, args: ('https://api.wandb.ai/files/wasiim/tempo_ml_training/3rhpz40q/file_stream',), kwargs: {'json': {'complete': False, 'failed': False, 'dropped': 0, 'uploaded': []}}
2022-04-10 14:07:25,210 WARNING FileStreamThread:28088 [file_stream.py:request_with_retry():594] requests_with_retry encountered retryable exception: HTTPSConnectionPool(host='api.wandb.ai', port=443): Max retries exceeded with url: /files/wasiim/tempo_ml_training/3rhpz40q/file_stream (Caused by NewConnectionError('<urllib3.connection.HTTPSConnection object at 0x000001F8E3824190>: Failed to establish a new connection: [Errno 11001] getaddrinfo failed')). func: <bound method Session.post of <requests.sessions.Session object at 0x000001F8E3787310>>, args: ('https://api.wandb.ai/files/wasiim/tempo_ml_training/3rhpz40q/file_stream',), kwargs: {'json': {'complete': False, 'failed': False, 'dropped': 0, 'uploaded': []}}
2022-04-10 14:08:00,766 WARNING FileStreamThread:28088 [file_stream.py:request_with_retry():594] requests_with_retry encountered retryable exception: HTTPSConnectionPool(host='api.wandb.ai', port=443): Max retries exceeded with url: /files/wasiim/tempo_ml_training/3rhpz40q/file_stream (Caused by NewConnectionError('<urllib3.connection.HTTPSConnection object at 0x000001F8E38247F0>: Failed to establish a new connection: [Errno 11001] getaddrinfo failed')). func: <bound method Session.post of <requests.sessions.Session object at 0x000001F8E3787310>>, args: ('https://api.wandb.ai/files/wasiim/tempo_ml_training/3rhpz40q/file_stream',), kwargs: {'json': {'complete': False, 'failed': False, 'dropped': 0, 'uploaded': []}}
2022-04-10 20:03:04,832 WARNING FileStreamThread:28088 [file_stream.py:request_with_retry():594] requests_with_retry encountered retryable exception: ('Connection aborted.', TimeoutError(10060, 'A connection attempt failed because the connected party did not properly respond after a period of time, or established connection failed because connected host has failed to respond', None, 10060, None)). func: <bound method Session.post of <requests.sessions.Session object at 0x000001F8E3787310>>, args: ('https://api.wandb.ai/files/wasiim/tempo_ml_training/3rhpz40q/file_stream',), kwargs: {'json': {'complete': False, 'failed': False, 'dropped': 0, 'uploaded': []}}
2022-04-10 20:03:18,124 WARNING FileStreamThread:28088 [file_stream.py:request_with_retry():594] requests_with_retry encountered retryable exception: HTTPSConnectionPool(host='api.wandb.ai', port=443): Max retries exceeded with url: /files/wasiim/tempo_ml_training/3rhpz40q/file_stream (Caused by NewConnectionError('<urllib3.connection.HTTPSConnection object at 0x000001F8E381E1C0>: Failed to establish a new connection: [Errno 11001] getaddrinfo failed')). func: <bound method Session.post of <requests.sessions.Session object at 0x000001F8E3787310>>, args: ('https://api.wandb.ai/files/wasiim/tempo_ml_training/3rhpz40q/file_stream',), kwargs: {'json': {'complete': False, 'failed': False, 'dropped': 0, 'uploaded': []}}
2022-04-10 20:03:34,054 WARNING FileStreamThread:28088 [file_stream.py:request_with_retry():594] requests_with_retry encountered retryable exception: HTTPSConnectionPool(host='api.wandb.ai', port=443): Max retries exceeded with url: /files/wasiim/tempo_ml_training/3rhpz40q/file_stream (Caused by NewConnectionError('<urllib3.connection.HTTPSConnection object at 0x000001F8E381EC40>: Failed to establish a new connection: [Errno 11001] getaddrinfo failed')). func: <bound method Session.post of <requests.sessions.Session object at 0x000001F8E3787310>>, args: ('https://api.wandb.ai/files/wasiim/tempo_ml_training/3rhpz40q/file_stream',), kwargs: {'json': {'complete': False, 'failed': False, 'dropped': 0, 'uploaded': []}}
2022-04-10 20:03:53,196 WARNING FileStreamThread:28088 [file_stream.py:request_with_retry():594] requests_with_retry encountered retryable exception: HTTPSConnectionPool(host='api.wandb.ai', port=443): Max retries exceeded with url: /files/wasiim/tempo_ml_training/3rhpz40q/file_stream (Caused by NewConnectionError('<urllib3.connection.HTTPSConnection object at 0x000001F8E381EA90>: Failed to establish a new connection: [Errno 11001] getaddrinfo failed')). func: <bound method Session.post of <requests.sessions.Session object at 0x000001F8E3787310>>, args: ('https://api.wandb.ai/files/wasiim/tempo_ml_training/3rhpz40q/file_stream',), kwargs: {'json': {'complete': False, 'failed': False, 'dropped': 0, 'uploaded': []}}
2022-04-10 20:04:11,284 WARNING FileStreamThread:28088 [file_stream.py:request_with_retry():594] requests_with_retry encountered retryable exception: HTTPSConnectionPool(host='api.wandb.ai', port=443): Max retries exceeded with url: /files/wasiim/tempo_ml_training/3rhpz40q/file_stream (Caused by NewConnectionError('<urllib3.connection.HTTPSConnection object at 0x000001F8E381E430>: Failed to establish a new connection: [Errno 11001] getaddrinfo failed')). func: <bound method Session.post of <requests.sessions.Session object at 0x000001F8E3787310>>, args: ('https://api.wandb.ai/files/wasiim/tempo_ml_training/3rhpz40q/file_stream',), kwargs: {'json': {'complete': False, 'failed': False, 'dropped': 0, 'uploaded': []}}
2022-04-10 20:04:46,473 WARNING FileStreamThread:28088 [file_stream.py:request_with_retry():594] requests_with_retry encountered retryable exception: HTTPSConnectionPool(host='api.wandb.ai', port=443): Max retries exceeded with url: /files/wasiim/tempo_ml_training/3rhpz40q/file_stream (Caused by NewConnectionError('<urllib3.connection.HTTPSConnection object at 0x000001F8E3837100>: Failed to establish a new connection: [Errno 11001] getaddrinfo failed')). func: <bound method Session.post of <requests.sessions.Session object at 0x000001F8E3787310>>, args: ('https://api.wandb.ai/files/wasiim/tempo_ml_training/3rhpz40q/file_stream',), kwargs: {'json': {'complete': False, 'failed': False, 'dropped': 0, 'uploaded': []}}
2022-04-10 20:05:56,074 WARNING FileStreamThread:28088 [file_stream.py:request_with_retry():594] requests_with_retry encountered retryable exception: HTTPSConnectionPool(host='api.wandb.ai', port=443): Max retries exceeded with url: /files/wasiim/tempo_ml_training/3rhpz40q/file_stream (Caused by NewConnectionError('<urllib3.connection.HTTPSConnection object at 0x000001F8E38375E0>: Failed to establish a new connection: [Errno 11001] getaddrinfo failed')). func: <bound method Session.post of <requests.sessions.Session object at 0x000001F8E3787310>>, args: ('https://api.wandb.ai/files/wasiim/tempo_ml_training/3rhpz40q/file_stream',), kwargs: {'json': {'complete': False, 'failed': False, 'dropped': 0, 'uploaded': []}}
2022-04-10 21:57:13,246 WARNING FileStreamThread:28088 [file_stream.py:request_with_retry():594] requests_with_retry encountered retryable exception: ('Connection aborted.', TimeoutError(10060, 'A connection attempt failed because the connected party did not properly respond after a period of time, or established connection failed because connected host has failed to respond', None, 10060, None)). func: <bound method Session.post of <requests.sessions.Session object at 0x000001F8E3787310>>, args: ('https://api.wandb.ai/files/wasiim/tempo_ml_training/3rhpz40q/file_stream',), kwargs: {'json': {'complete': False, 'failed': False, 'dropped': 0, 'uploaded': []}}
2022-04-10 21:57:26,590 WARNING FileStreamThread:28088 [file_stream.py:request_with_retry():594] requests_with_retry encountered retryable exception: HTTPSConnectionPool(host='api.wandb.ai', port=443): Max retries exceeded with url: /files/wasiim/tempo_ml_training/3rhpz40q/file_stream (Caused by NewConnectionError('<urllib3.connection.HTTPSConnection object at 0x000001F8E3836B50>: Failed to establish a new connection: [Errno 11001] getaddrinfo failed')). func: <bound method Session.post of <requests.sessions.Session object at 0x000001F8E3787310>>, args: ('https://api.wandb.ai/files/wasiim/tempo_ml_training/3rhpz40q/file_stream',), kwargs: {'json': {'complete': False, 'failed': False, 'dropped': 0, 'uploaded': []}}
2022-04-10 21:57:41,933 WARNING FileStreamThread:28088 [file_stream.py:request_with_retry():594] requests_with_retry encountered retryable exception: HTTPSConnectionPool(host='api.wandb.ai', port=443): Max retries exceeded with url: /files/wasiim/tempo_ml_training/3rhpz40q/file_stream (Caused by NewConnectionError('<urllib3.connection.HTTPSConnection object at 0x000001F8E3836A90>: Failed to establish a new connection: [Errno 11001] getaddrinfo failed')). func: <bound method Session.post of <requests.sessions.Session object at 0x000001F8E3787310>>, args: ('https://api.wandb.ai/files/wasiim/tempo_ml_training/3rhpz40q/file_stream',), kwargs: {'json': {'complete': False, 'failed': False, 'dropped': 0, 'uploaded': []}}
2022-04-10 21:58:02,717 WARNING FileStreamThread:28088 [file_stream.py:request_with_retry():594] requests_with_retry encountered retryable exception: HTTPSConnectionPool(host='api.wandb.ai', port=443): Max retries exceeded with url: /files/wasiim/tempo_ml_training/3rhpz40q/file_stream (Caused by NewConnectionError('<urllib3.connection.HTTPSConnection object at 0x000001F8E3836160>: Failed to establish a new connection: [Errno 11001] getaddrinfo failed')). func: <bound method Session.post of <requests.sessions.Session object at 0x000001F8E3787310>>, args: ('https://api.wandb.ai/files/wasiim/tempo_ml_training/3rhpz40q/file_stream',), kwargs: {'json': {'complete': False, 'failed': False, 'dropped': 0, 'uploaded': []}}
2022-04-10 21:58:19,665 WARNING FileStreamThread:28088 [file_stream.py:request_with_retry():594] requests_with_retry encountered retryable exception: HTTPSConnectionPool(host='api.wandb.ai', port=443): Max retries exceeded with url: /files/wasiim/tempo_ml_training/3rhpz40q/file_stream (Caused by NewConnectionError('<urllib3.connection.HTTPSConnection object at 0x000001F8E3836760>: Failed to establish a new connection: [Errno 11001] getaddrinfo failed')). func: <bound method Session.post of <requests.sessions.Session object at 0x000001F8E3787310>>, args: ('https://api.wandb.ai/files/wasiim/tempo_ml_training/3rhpz40q/file_stream',), kwargs: {'json': {'complete': False, 'failed': False, 'dropped': 0, 'uploaded': []}}
2022-04-10 21:58:54,257 WARNING FileStreamThread:28088 [file_stream.py:request_with_retry():594] requests_with_retry encountered retryable exception: HTTPSConnectionPool(host='api.wandb.ai', port=443): Max retries exceeded with url: /files/wasiim/tempo_ml_training/3rhpz40q/file_stream (Caused by NewConnectionError('<urllib3.connection.HTTPSConnection object at 0x000001F8E3836130>: Failed to establish a new connection: [Errno 11001] getaddrinfo failed')). func: <bound method Session.post of <requests.sessions.Session object at 0x000001F8E3787310>>, args: ('https://api.wandb.ai/files/wasiim/tempo_ml_training/3rhpz40q/file_stream',), kwargs: {'json': {'complete': False, 'failed': False, 'dropped': 0, 'uploaded': []}}
2022-04-10 21:59:58,909 WARNING FileStreamThread:28088 [file_stream.py:request_with_retry():594] requests_with_retry encountered retryable exception: HTTPSConnectionPool(host='api.wandb.ai', port=443): Max retries exceeded with url: /files/wasiim/tempo_ml_training/3rhpz40q/file_stream (Caused by NewConnectionError('<urllib3.connection.HTTPSConnection object at 0x000001F8E3836760>: Failed to establish a new connection: [Errno 11001] getaddrinfo failed')). func: <bound method Session.post of <requests.sessions.Session object at 0x000001F8E3787310>>, args: ('https://api.wandb.ai/files/wasiim/tempo_ml_training/3rhpz40q/file_stream',), kwargs: {'json': {'complete': False, 'failed': False, 'dropped': 0, 'uploaded': []}}
2022-04-11 09:47:58,550 WARNING FileStreamThread:28088 [file_stream.py:request_with_retry():594] requests_with_retry encountered retryable exception: ('Connection aborted.', TimeoutError(10060, 'A connection attempt failed because the connected party did not properly respond after a period of time, or established connection failed because connected host has failed to respond', None, 10060, None)). func: <bound method Session.post of <requests.sessions.Session object at 0x000001F8E3787310>>, args: ('https://api.wandb.ai/files/wasiim/tempo_ml_training/3rhpz40q/file_stream',), kwargs: {'json': {'complete': False, 'failed': False, 'dropped': 0, 'uploaded': []}}
2022-04-11 09:48:00,823 WARNING FileStreamThread:28088 [file_stream.py:request_with_retry():594] requests_with_retry encountered retryable exception: HTTPSConnectionPool(host='api.wandb.ai', port=443): Max retries exceeded with url: /files/wasiim/tempo_ml_training/3rhpz40q/file_stream (Caused by NewConnectionError('<urllib3.connection.HTTPSConnection object at 0x000001F8E3827160>: Failed to establish a new connection: [Errno 11001] getaddrinfo failed')). func: <bound method Session.post of <requests.sessions.Session object at 0x000001F8E3787310>>, args: ('https://api.wandb.ai/files/wasiim/tempo_ml_training/3rhpz40q/file_stream',), kwargs: {'json': {'complete': False, 'failed': False, 'dropped': 0, 'uploaded': []}}
2022-04-11 09:48:05,667 WARNING FileStreamThread:28088 [file_stream.py:request_with_retry():594] requests_with_retry encountered retryable exception: HTTPSConnectionPool(host='api.wandb.ai', port=443): Max retries exceeded with url: /files/wasiim/tempo_ml_training/3rhpz40q/file_stream (Caused by NewConnectionError('<urllib3.connection.HTTPSConnection object at 0x000001F8E3827460>: Failed to establish a new connection: [Errno 11001] getaddrinfo failed')). func: <bound method Session.post of <requests.sessions.Session object at 0x000001F8E3787310>>, args: ('https://api.wandb.ai/files/wasiim/tempo_ml_training/3rhpz40q/file_stream',), kwargs: {'json': {'complete': False, 'failed': False, 'dropped': 0, 'uploaded': []}}
2022-04-11 09:48:15,960 WARNING FileStreamThread:28088 [file_stream.py:request_with_retry():594] requests_with_retry encountered retryable exception: HTTPSConnectionPool(host='api.wandb.ai', port=443): Max retries exceeded with url: /files/wasiim/tempo_ml_training/3rhpz40q/file_stream (Caused by NewConnectionError('<urllib3.connection.HTTPSConnection object at 0x000001F8E3827BE0>: Failed to establish a new connection: [Errno 11001] getaddrinfo failed')). func: <bound method Session.post of <requests.sessions.Session object at 0x000001F8E3787310>>, args: ('https://api.wandb.ai/files/wasiim/tempo_ml_training/3rhpz40q/file_stream',), kwargs: {'json': {'complete': False, 'failed': False, 'dropped': 0, 'uploaded': []}}
2022-04-11 11:00:07,111 WARNING FileStreamThread:28088 [file_stream.py:request_with_retry():594] requests_with_retry encountered retryable exception: HTTPSConnectionPool(host='api.wandb.ai', port=443): Max retries exceeded with url: /files/wasiim/tempo_ml_training/3rhpz40q/file_stream (Caused by NewConnectionError('<urllib3.connection.HTTPSConnection object at 0x000001F8E3827160>: Failed to establish a new connection: [Errno 11001] getaddrinfo failed')). func: <bound method Session.post of <requests.sessions.Session object at 0x000001F8E3787310>>, args: ('https://api.wandb.ai/files/wasiim/tempo_ml_training/3rhpz40q/file_stream',), kwargs: {'json': {'complete': False, 'failed': False, 'dropped': 0, 'uploaded': []}}
2022-04-11 12:00:12,090 WARNING FileStreamThread:28088 [file_stream.py:request_with_retry():594] requests_with_retry encountered retryable exception: ('Connection aborted.', TimeoutError(10060, 'A connection attempt failed because the connected party did not properly respond after a period of time, or established connection failed because connected host has failed to respond', None, 10060, None)). func: <bound method Session.post of <requests.sessions.Session object at 0x000001F8E3787310>>, args: ('https://api.wandb.ai/files/wasiim/tempo_ml_training/3rhpz40q/file_stream',), kwargs: {'json': {'complete': False, 'failed': False, 'dropped': 0, 'uploaded': []}}
2022-04-11 13:56:52,322 WARNING FileStreamThread:28088 [file_stream.py:request_with_retry():594] requests_with_retry encountered retryable exception: ('Connection aborted.', ConnectionResetError(10054, 'An existing connection was forcibly closed by the remote host', None, 10054, None)). func: <bound method Session.post of <requests.sessions.Session object at 0x000001F8E3787310>>, args: ('https://api.wandb.ai/files/wasiim/tempo_ml_training/3rhpz40q/file_stream',), kwargs: {'json': {'complete': False, 'failed': False, 'dropped': 0, 'uploaded': []}}
2022-04-11 23:12:09,800 WARNING FileStreamThread:28088 [file_stream.py:request_with_retry():594] requests_with_retry encountered retryable exception: ('Connection aborted.', ConnectionResetError(10054, 'An existing connection was forcibly closed by the remote host', None, 10054, None)). func: <bound method Session.post of <requests.sessions.Session object at 0x000001F8E3787310>>, args: ('https://api.wandb.ai/files/wasiim/tempo_ml_training/3rhpz40q/file_stream',), kwargs: {'json': {'complete': False, 'failed': False, 'dropped': 0, 'uploaded': []}}
2022-04-11 23:13:52,221 WARNING FileStreamThread:28088 [file_stream.py:request_with_retry():594] requests_with_retry encountered retryable exception: ('Connection aborted.', ConnectionAbortedError(10053, 'An established connection was aborted by the software in your host machine', None, 10053, None)). func: <bound method Session.post of <requests.sessions.Session object at 0x000001F8E3787310>>, args: ('https://api.wandb.ai/files/wasiim/tempo_ml_training/3rhpz40q/file_stream',), kwargs: {'json': {'complete': False, 'failed': False, 'dropped': 0, 'uploaded': []}}
2022-04-11 23:13:54,432 WARNING FileStreamThread:28088 [file_stream.py:request_with_retry():594] requests_with_retry encountered retryable exception: HTTPSConnectionPool(host='api.wandb.ai', port=443): Max retries exceeded with url: /files/wasiim/tempo_ml_training/3rhpz40q/file_stream (Caused by NewConnectionError('<urllib3.connection.HTTPSConnection object at 0x000001F8E381E3A0>: Failed to establish a new connection: [Errno 11001] getaddrinfo failed')). func: <bound method Session.post of <requests.sessions.Session object at 0x000001F8E3787310>>, args: ('https://api.wandb.ai/files/wasiim/tempo_ml_training/3rhpz40q/file_stream',), kwargs: {'json': {'complete': False, 'failed': False, 'dropped': 0, 'uploaded': []}}
2022-04-11 23:13:58,463 WARNING FileStreamThread:28088 [file_stream.py:request_with_retry():594] requests_with_retry encountered retryable exception: HTTPSConnectionPool(host='api.wandb.ai', port=443): Max retries exceeded with url: /files/wasiim/tempo_ml_training/3rhpz40q/file_stream (Caused by NewConnectionError('<urllib3.connection.HTTPSConnection object at 0x000001F8E381E0D0>: Failed to establish a new connection: [Errno 11001] getaddrinfo failed')). func: <bound method Session.post of <requests.sessions.Session object at 0x000001F8E3787310>>, args: ('https://api.wandb.ai/files/wasiim/tempo_ml_training/3rhpz40q/file_stream',), kwargs: {'json': {'complete': False, 'failed': False, 'dropped': 0, 'uploaded': []}}
2022-04-11 23:14:07,531 WARNING FileStreamThread:28088 [file_stream.py:request_with_retry():594] requests_with_retry encountered retryable exception: HTTPSConnectionPool(host='api.wandb.ai', port=443): Max retries exceeded with url: /files/wasiim/tempo_ml_training/3rhpz40q/file_stream (Caused by NewConnectionError('<urllib3.connection.HTTPSConnection object at 0x000001F8E381E970>: Failed to establish a new connection: [Errno 11001] getaddrinfo failed')). func: <bound method Session.post of <requests.sessions.Session object at 0x000001F8E3787310>>, args: ('https://api.wandb.ai/files/wasiim/tempo_ml_training/3rhpz40q/file_stream',), kwargs: {'json': {'complete': False, 'failed': False, 'dropped': 0, 'uploaded': []}}
2022-04-11 23:14:27,198 WARNING FileStreamThread:28088 [file_stream.py:request_with_retry():594] requests_with_retry encountered retryable exception: HTTPSConnectionPool(host='api.wandb.ai', port=443): Max retries exceeded with url: /files/wasiim/tempo_ml_training/3rhpz40q/file_stream (Caused by NewConnectionError('<urllib3.connection.HTTPSConnection object at 0x000001F8E381E430>: Failed to establish a new connection: [Errno 11001] getaddrinfo failed')). func: <bound method Session.post of <requests.sessions.Session object at 0x000001F8E3787310>>, args: ('https://api.wandb.ai/files/wasiim/tempo_ml_training/3rhpz40q/file_stream',), kwargs: {'json': {'complete': False, 'failed': False, 'dropped': 0, 'uploaded': []}}
2022-04-12 08:34:47,855 WARNING FileStreamThread:28088 [file_stream.py:request_with_retry():594] requests_with_retry encountered retryable exception: ('Connection aborted.', ConnectionResetError(10054, 'An existing connection was forcibly closed by the remote host', None, 10054, None)). func: <bound method Session.post of <requests.sessions.Session object at 0x000001F8E3787310>>, args: ('https://api.wandb.ai/files/wasiim/tempo_ml_training/3rhpz40q/file_stream',), kwargs: {'json': {'complete': False, 'failed': False, 'dropped': 0, 'uploaded': []}}
2022-04-12 09:45:41,103 WARNING FileStreamThread:28088 [file_stream.py:request_with_retry():594] requests_with_retry encountered retryable exception: ('Connection aborted.', ConnectionAbortedError(10053, 'An established connection was aborted by the software in your host machine', None, 10053, None)). func: <bound method Session.post of <requests.sessions.Session object at 0x000001F8E3787310>>, args: ('https://api.wandb.ai/files/wasiim/tempo_ml_training/3rhpz40q/file_stream',), kwargs: {'json': {'complete': False, 'failed': False, 'dropped': 0, 'uploaded': []}}
2022-04-12 10:57:13,070 WARNING FileStreamThread:28088 [file_stream.py:request_with_retry():594] requests_with_retry encountered retryable exception: ('Connection aborted.', ConnectionResetError(10054, 'An existing connection was forcibly closed by the remote host', None, 10054, None)). func: <bound method Session.post of <requests.sessions.Session object at 0x000001F8E3787310>>, args: ('https://api.wandb.ai/files/wasiim/tempo_ml_training/3rhpz40q/file_stream',), kwargs: {'json': {'complete': False, 'failed': False, 'dropped': 0, 'uploaded': []}}
2022-04-12 12:15:17,718 WARNING FileStreamThread:28088 [file_stream.py:request_with_retry():594] requests_with_retry encountered retryable exception: ('Connection aborted.', TimeoutError(10060, 'A connection attempt failed because the connected party did not properly respond after a period of time, or established connection failed because connected host has failed to respond', None, 10060, None)). func: <bound method Session.post of <requests.sessions.Session object at 0x000001F8E3787310>>, args: ('https://api.wandb.ai/files/wasiim/tempo_ml_training/3rhpz40q/file_stream',), kwargs: {'json': {'complete': False, 'failed': False, 'dropped': 0, 'uploaded': []}}
2022-04-12 13:07:13,004 WARNING FileStreamThread:28088 [file_stream.py:request_with_retry():594] requests_with_retry encountered retryable exception: ('Connection aborted.', TimeoutError(10060, 'A connection attempt failed because the connected party did not properly respond after a period of time, or established connection failed because connected host has failed to respond', None, 10060, None)). func: <bound method Session.post of <requests.sessions.Session object at 0x000001F8E3787310>>, args: ('https://api.wandb.ai/files/wasiim/tempo_ml_training/3rhpz40q/file_stream',), kwargs: {'json': {'complete': False, 'failed': False, 'dropped': 0, 'uploaded': []}}
2022-04-12 14:31:41,932 WARNING FileStreamThread:28088 [file_stream.py:request_with_retry():594] requests_with_retry encountered retryable exception: ('Connection aborted.', TimeoutError(10060, 'A connection attempt failed because the connected party did not properly respond after a period of time, or established connection failed because connected host has failed to respond', None, 10060, None)). func: <bound method Session.post of <requests.sessions.Session object at 0x000001F8E3787310>>, args: ('https://api.wandb.ai/files/wasiim/tempo_ml_training/3rhpz40q/file_stream',), kwargs: {'json': {'complete': False, 'failed': False, 'dropped': 0, 'uploaded': []}}
2022-04-12 20:05:14,376 WARNING FileStreamThread:28088 [file_stream.py:request_with_retry():594] requests_with_retry encountered retryable exception: HTTPSConnectionPool(host='api.wandb.ai', port=443): Max retries exceeded with url: /files/wasiim/tempo_ml_training/3rhpz40q/file_stream (Caused by NewConnectionError('<urllib3.connection.HTTPSConnection object at 0x000001F8E3836400>: Failed to establish a new connection: [Errno 11001] getaddrinfo failed')). func: <bound method Session.post of <requests.sessions.Session object at 0x000001F8E3787310>>, args: ('https://api.wandb.ai/files/wasiim/tempo_ml_training/3rhpz40q/file_stream',), kwargs: {'json': {'complete': False, 'failed': False, 'dropped': 0, 'uploaded': []}}
2022-04-12 20:05:16,660 WARNING FileStreamThread:28088 [file_stream.py:request_with_retry():594] requests_with_retry encountered retryable exception: HTTPSConnectionPool(host='api.wandb.ai', port=443): Max retries exceeded with url: /files/wasiim/tempo_ml_training/3rhpz40q/file_stream (Caused by NewConnectionError('<urllib3.connection.HTTPSConnection object at 0x000001F8E381E280>: Failed to establish a new connection: [Errno 11001] getaddrinfo failed')). func: <bound method Session.post of <requests.sessions.Session object at 0x000001F8E3787310>>, args: ('https://api.wandb.ai/files/wasiim/tempo_ml_training/3rhpz40q/file_stream',), kwargs: {'json': {'complete': False, 'failed': False, 'dropped': 0, 'uploaded': []}}
2022-04-12 20:05:21,559 WARNING FileStreamThread:28088 [file_stream.py:request_with_retry():594] requests_with_retry encountered retryable exception: HTTPSConnectionPool(host='api.wandb.ai', port=443): Max retries exceeded with url: /files/wasiim/tempo_ml_training/3rhpz40q/file_stream (Caused by NewConnectionError('<urllib3.connection.HTTPSConnection object at 0x000001F8E381E340>: Failed to establish a new connection: [Errno 11001] getaddrinfo failed')). func: <bound method Session.post of <requests.sessions.Session object at 0x000001F8E3787310>>, args: ('https://api.wandb.ai/files/wasiim/tempo_ml_training/3rhpz40q/file_stream',), kwargs: {'json': {'complete': False, 'failed': False, 'dropped': 0, 'uploaded': []}}
2022-04-12 20:05:30,554 WARNING FileStreamThread:28088 [file_stream.py:request_with_retry():594] requests_with_retry encountered retryable exception: HTTPSConnectionPool(host='api.wandb.ai', port=443): Max retries exceeded with url: /files/wasiim/tempo_ml_training/3rhpz40q/file_stream (Caused by NewConnectionError('<urllib3.connection.HTTPSConnection object at 0x000001F8E381EFD0>: Failed to establish a new connection: [Errno 11001] getaddrinfo failed')). func: <bound method Session.post of <requests.sessions.Session object at 0x000001F8E3787310>>, args: ('https://api.wandb.ai/files/wasiim/tempo_ml_training/3rhpz40q/file_stream',), kwargs: {'json': {'complete': False, 'failed': False, 'dropped': 0, 'uploaded': []}}
2022-04-12 20:05:49,352 WARNING FileStreamThread:28088 [file_stream.py:request_with_retry():594] requests_with_retry encountered retryable exception: HTTPSConnectionPool(host='api.wandb.ai', port=443): Max retries exceeded with url: /files/wasiim/tempo_ml_training/3rhpz40q/file_stream (Caused by NewConnectionError('<urllib3.connection.HTTPSConnection object at 0x000001F8E381EBB0>: Failed to establish a new connection: [Errno 11001] getaddrinfo failed')). func: <bound method Session.post of <requests.sessions.Session object at 0x000001F8E3787310>>, args: ('https://api.wandb.ai/files/wasiim/tempo_ml_training/3rhpz40q/file_stream',), kwargs: {'json': {'complete': False, 'failed': False, 'dropped': 0, 'uploaded': []}}
2022-04-13 00:44:21,878 WARNING FileStreamThread:28088 [file_stream.py:request_with_retry():594] requests_with_retry encountered retryable exception: ('Connection aborted.', ConnectionResetError(10054, 'An existing connection was forcibly closed by the remote host', None, 10054, None)). func: <bound method Session.post of <requests.sessions.Session object at 0x000001F8E3787310>>, args: ('https://api.wandb.ai/files/wasiim/tempo_ml_training/3rhpz40q/file_stream',), kwargs: {'json': {'complete': False, 'failed': False, 'dropped': 0, 'uploaded': []}}
2022-04-13 09:20:07,865 WARNING FileStreamThread:28088 [file_stream.py:request_with_retry():594] requests_with_retry encountered retryable exception: ('Connection aborted.', ConnectionResetError(10054, 'An existing connection was forcibly closed by the remote host', None, 10054, None)). func: <bound method Session.post of <requests.sessions.Session object at 0x000001F8E3787310>>, args: ('https://api.wandb.ai/files/wasiim/tempo_ml_training/3rhpz40q/file_stream',), kwargs: {'json': {'complete': False, 'failed': False, 'dropped': 0, 'uploaded': []}}
2022-04-13 09:20:22,322 WARNING FileStreamThread:28088 [file_stream.py:request_with_retry():594] requests_with_retry encountered retryable exception: HTTPSConnectionPool(host='api.wandb.ai', port=443): Max retries exceeded with url: /files/wasiim/tempo_ml_training/3rhpz40q/file_stream (Caused by NewConnectionError('<urllib3.connection.HTTPSConnection object at 0x000001F8E3824D60>: Failed to establish a new connection: [Errno 11001] getaddrinfo failed')). func: <bound method Session.post of <requests.sessions.Session object at 0x000001F8E3787310>>, args: ('https://api.wandb.ai/files/wasiim/tempo_ml_training/3rhpz40q/file_stream',), kwargs: {'json': {'complete': False, 'failed': False, 'dropped': 0, 'uploaded': []}}
2022-04-13 09:20:38,448 WARNING FileStreamThread:28088 [file_stream.py:request_with_retry():594] requests_with_retry encountered retryable exception: HTTPSConnectionPool(host='api.wandb.ai', port=443): Max retries exceeded with url: /files/wasiim/tempo_ml_training/3rhpz40q/file_stream (Caused by NewConnectionError('<urllib3.connection.HTTPSConnection object at 0x000001F8E3824FD0>: Failed to establish a new connection: [Errno 11001] getaddrinfo failed')). func: <bound method Session.post of <requests.sessions.Session object at 0x000001F8E3787310>>, args: ('https://api.wandb.ai/files/wasiim/tempo_ml_training/3rhpz40q/file_stream',), kwargs: {'json': {'complete': False, 'failed': False, 'dropped': 0, 'uploaded': []}}
2022-04-13 09:20:47,832 WARNING FileStreamThread:28088 [file_stream.py:request_with_retry():594] requests_with_retry encountered retryable exception: HTTPSConnectionPool(host='api.wandb.ai', port=443): Max retries exceeded with url: /files/wasiim/tempo_ml_training/3rhpz40q/file_stream (Caused by NewConnectionError('<urllib3.connection.HTTPSConnection object at 0x000001F8E3824B80>: Failed to establish a new connection: [Errno 11001] getaddrinfo failed')). func: <bound method Session.post of <requests.sessions.Session object at 0x000001F8E3787310>>, args: ('https://api.wandb.ai/files/wasiim/tempo_ml_training/3rhpz40q/file_stream',), kwargs: {'json': {'complete': False, 'failed': False, 'dropped': 0, 'uploaded': []}}
2022-04-13 09:21:16,122 WARNING FileStreamThread:28088 [file_stream.py:request_with_retry():594] requests_with_retry encountered retryable exception: HTTPSConnectionPool(host='api.wandb.ai', port=443): Max retries exceeded with url: /files/wasiim/tempo_ml_training/3rhpz40q/file_stream (Caused by NewConnectionError('<urllib3.connection.HTTPSConnection object at 0x000001F8E3827070>: Failed to establish a new connection: [Errno 11001] getaddrinfo failed')). func: <bound method Session.post of <requests.sessions.Session object at 0x000001F8E3787310>>, args: ('https://api.wandb.ai/files/wasiim/tempo_ml_training/3rhpz40q/file_stream',), kwargs: {'json': {'complete': False, 'failed': False, 'dropped': 0, 'uploaded': []}}
2022-04-13 09:21:52,105 WARNING FileStreamThread:28088 [file_stream.py:request_with_retry():594] requests_with_retry encountered retryable exception: HTTPSConnectionPool(host='api.wandb.ai', port=443): Max retries exceeded with url: /files/wasiim/tempo_ml_training/3rhpz40q/file_stream (Caused by NewConnectionError('<urllib3.connection.HTTPSConnection object at 0x000001F8E3827FD0>: Failed to establish a new connection: [Errno 11001] getaddrinfo failed')). func: <bound method Session.post of <requests.sessions.Session object at 0x000001F8E3787310>>, args: ('https://api.wandb.ai/files/wasiim/tempo_ml_training/3rhpz40q/file_stream',), kwargs: {'json': {'complete': False, 'failed': False, 'dropped': 0, 'uploaded': []}}
2022-04-13 09:23:11,082 WARNING FileStreamThread:28088 [file_stream.py:request_with_retry():594] requests_with_retry encountered retryable exception: HTTPSConnectionPool(host='api.wandb.ai', port=443): Max retries exceeded with url: /files/wasiim/tempo_ml_training/3rhpz40q/file_stream (Caused by NewConnectionError('<urllib3.connection.HTTPSConnection object at 0x000001F8E38270D0>: Failed to establish a new connection: [Errno 11001] getaddrinfo failed')). func: <bound method Session.post of <requests.sessions.Session object at 0x000001F8E3787310>>, args: ('https://api.wandb.ai/files/wasiim/tempo_ml_training/3rhpz40q/file_stream',), kwargs: {'json': {'complete': False, 'failed': False, 'dropped': 0, 'uploaded': []}}
2022-04-13 09:25:34,902 WARNING FileStreamThread:28088 [file_stream.py:request_with_retry():594] requests_with_retry encountered retryable exception: HTTPSConnectionPool(host='api.wandb.ai', port=443): Max retries exceeded with url: /files/wasiim/tempo_ml_training/3rhpz40q/file_stream (Caused by NewConnectionError('<urllib3.connection.HTTPSConnection object at 0x000001F8E3827760>: Failed to establish a new connection: [Errno 11001] getaddrinfo failed')). func: <bound method Session.post of <requests.sessions.Session object at 0x000001F8E3787310>>, args: ('https://api.wandb.ai/files/wasiim/tempo_ml_training/3rhpz40q/file_stream',), kwargs: {'json': {'complete': False, 'failed': False, 'dropped': 0, 'uploaded': []}}
2022-04-13 09:30:38,761 WARNING FileStreamThread:28088 [file_stream.py:request_with_retry():594] requests_with_retry encountered retryable exception: HTTPSConnectionPool(host='api.wandb.ai', port=443): Max retries exceeded with url: /files/wasiim/tempo_ml_training/3rhpz40q/file_stream (Caused by NewConnectionError('<urllib3.connection.HTTPSConnection object at 0x000001F8E38272B0>: Failed to establish a new connection: [Errno 11001] getaddrinfo failed')). func: <bound method Session.post of <requests.sessions.Session object at 0x000001F8E3787310>>, args: ('https://api.wandb.ai/files/wasiim/tempo_ml_training/3rhpz40q/file_stream',), kwargs: {'json': {'complete': False, 'failed': False, 'dropped': 0, 'uploaded': []}}
2022-04-13 09:35:44,417 WARNING FileStreamThread:28088 [file_stream.py:request_with_retry():594] requests_with_retry encountered retryable exception: HTTPSConnectionPool(host='api.wandb.ai', port=443): Max retries exceeded with url: /files/wasiim/tempo_ml_training/3rhpz40q/file_stream (Caused by NewConnectionError('<urllib3.connection.HTTPSConnection object at 0x000001F8E3827EB0>: Failed to establish a new connection: [Errno 11001] getaddrinfo failed')). func: <bound method Session.post of <requests.sessions.Session object at 0x000001F8E3787310>>, args: ('https://api.wandb.ai/files/wasiim/tempo_ml_training/3rhpz40q/file_stream',), kwargs: {'json': {'complete': False, 'failed': False, 'dropped': 0, 'uploaded': []}}
2022-04-13 09:40:45,228 WARNING FileStreamThread:28088 [file_stream.py:request_with_retry():594] requests_with_retry encountered retryable exception: HTTPSConnectionPool(host='api.wandb.ai', port=443): Max retries exceeded with url: /files/wasiim/tempo_ml_training/3rhpz40q/file_stream (Caused by NewConnectionError('<urllib3.connection.HTTPSConnection object at 0x000001F8E3827130>: Failed to establish a new connection: [Errno 11001] getaddrinfo failed')). func: <bound method Session.post of <requests.sessions.Session object at 0x000001F8E3787310>>, args: ('https://api.wandb.ai/files/wasiim/tempo_ml_training/3rhpz40q/file_stream',), kwargs: {'json': {'complete': False, 'failed': False, 'dropped': 0, 'uploaded': []}}
2022-04-13 11:30:49,897 WARNING FileStreamThread:28088 [file_stream.py:request_with_retry():594] requests_with_retry encountered retryable exception: 500 Server Error: Internal Server Error for url: https://api.wandb.ai/files/wasiim/tempo_ml_training/3rhpz40q/file_stream. func: <bound method Session.post of <requests.sessions.Session object at 0x000001F8E3787310>>, args: ('https://api.wandb.ai/files/wasiim/tempo_ml_training/3rhpz40q/file_stream',), kwargs: {'json': {'complete': False, 'failed': False, 'dropped': 0, 'uploaded': []}}
2022-04-13 12:00:30,451 WARNING FileStreamThread:28088 [file_stream.py:request_with_retry():594] requests_with_retry encountered retryable exception: ('Connection aborted.', ConnectionResetError(10054, 'An existing connection was forcibly closed by the remote host', None, 10054, None)). func: <bound method Session.post of <requests.sessions.Session object at 0x000001F8E3787310>>, args: ('https://api.wandb.ai/files/wasiim/tempo_ml_training/3rhpz40q/file_stream',), kwargs: {'json': {'complete': False, 'failed': False, 'dropped': 0, 'uploaded': []}}
2022-04-13 13:13:03,847 WARNING FileStreamThread:28088 [file_stream.py:request_with_retry():594] requests_with_retry encountered retryable exception: ('Connection aborted.', ConnectionResetError(10054, 'An existing connection was forcibly closed by the remote host', None, 10054, None)). func: <bound method Session.post of <requests.sessions.Session object at 0x000001F8E3787310>>, args: ('https://api.wandb.ai/files/wasiim/tempo_ml_training/3rhpz40q/file_stream',), kwargs: {'json': {'complete': False, 'failed': False, 'dropped': 0, 'uploaded': []}}
2022-04-13 14:03:30,243 WARNING FileStreamThread:28088 [file_stream.py:request_with_retry():594] requests_with_retry encountered retryable exception: ('Connection aborted.', TimeoutError(10060, 'A connection attempt failed because the connected party did not properly respond after a period of time, or established connection failed because connected host has failed to respond', None, 10060, None)). func: <bound method Session.post of <requests.sessions.Session object at 0x000001F8E3787310>>, args: ('https://api.wandb.ai/files/wasiim/tempo_ml_training/3rhpz40q/file_stream',), kwargs: {'json': {'complete': False, 'failed': False, 'dropped': 0, 'uploaded': []}}
2022-04-13 15:02:10,708 WARNING FileStreamThread:28088 [file_stream.py:request_with_retry():594] requests_with_retry encountered retryable exception: ('Connection aborted.', TimeoutError(10060, 'A connection attempt failed because the connected party did not properly respond after a period of time, or established connection failed because connected host has failed to respond', None, 10060, None)). func: <bound method Session.post of <requests.sessions.Session object at 0x000001F8E3787310>>, args: ('https://api.wandb.ai/files/wasiim/tempo_ml_training/3rhpz40q/file_stream',), kwargs: {'json': {'complete': False, 'failed': False, 'dropped': 0, 'uploaded': []}}
2022-04-13 16:31:51,330 WARNING FileStreamThread:28088 [file_stream.py:request_with_retry():594] requests_with_retry encountered retryable exception: 500 Server Error: Internal Server Error for url: https://api.wandb.ai/files/wasiim/tempo_ml_training/3rhpz40q/file_stream. func: <bound method Session.post of <requests.sessions.Session object at 0x000001F8E3787310>>, args: ('https://api.wandb.ai/files/wasiim/tempo_ml_training/3rhpz40q/file_stream',), kwargs: {'json': {'complete': False, 'failed': False, 'dropped': 0, 'uploaded': []}}
2022-04-13 18:30:51,815 WARNING FileStreamThread:28088 [file_stream.py:request_with_retry():594] requests_with_retry encountered retryable exception: 500 Server Error: Internal Server Error for url: https://api.wandb.ai/files/wasiim/tempo_ml_training/3rhpz40q/file_stream. func: <bound method Session.post of <requests.sessions.Session object at 0x000001F8E3787310>>, args: ('https://api.wandb.ai/files/wasiim/tempo_ml_training/3rhpz40q/file_stream',), kwargs: {'json': {'complete': False, 'failed': False, 'dropped': 0, 'uploaded': []}}
2022-04-13 20:35:35,517 WARNING FileStreamThread:28088 [file_stream.py:request_with_retry():594] requests_with_retry encountered retryable exception: HTTPSConnectionPool(host='api.wandb.ai', port=443): Max retries exceeded with url: /files/wasiim/tempo_ml_training/3rhpz40q/file_stream (Caused by NewConnectionError('<urllib3.connection.HTTPSConnection object at 0x000001F8E3836670>: Failed to establish a new connection: [Errno 11001] getaddrinfo failed')). func: <bound method Session.post of <requests.sessions.Session object at 0x000001F8E3787310>>, args: ('https://api.wandb.ai/files/wasiim/tempo_ml_training/3rhpz40q/file_stream',), kwargs: {'json': {'complete': False, 'failed': False, 'dropped': 0, 'uploaded': []}}
2022-04-13 20:35:37,899 WARNING FileStreamThread:28088 [file_stream.py:request_with_retry():594] requests_with_retry encountered retryable exception: HTTPSConnectionPool(host='api.wandb.ai', port=443): Max retries exceeded with url: /files/wasiim/tempo_ml_training/3rhpz40q/file_stream (Caused by NewConnectionError('<urllib3.connection.HTTPSConnection object at 0x000001F8E3824EE0>: Failed to establish a new connection: [Errno 11001] getaddrinfo failed')). func: <bound method Session.post of <requests.sessions.Session object at 0x000001F8E3787310>>, args: ('https://api.wandb.ai/files/wasiim/tempo_ml_training/3rhpz40q/file_stream',), kwargs: {'json': {'complete': False, 'failed': False, 'dropped': 0, 'uploaded': []}}
2022-04-13 20:35:42,508 WARNING FileStreamThread:28088 [file_stream.py:request_with_retry():594] requests_with_retry encountered retryable exception: HTTPSConnectionPool(host='api.wandb.ai', port=443): Max retries exceeded with url: /files/wasiim/tempo_ml_training/3rhpz40q/file_stream (Caused by NewConnectionError('<urllib3.connection.HTTPSConnection object at 0x000001F8E3824BB0>: Failed to establish a new connection: [Errno 11001] getaddrinfo failed')). func: <bound method Session.post of <requests.sessions.Session object at 0x000001F8E3787310>>, args: ('https://api.wandb.ai/files/wasiim/tempo_ml_training/3rhpz40q/file_stream',), kwargs: {'json': {'complete': False, 'failed': False, 'dropped': 0, 'uploaded': []}}
2022-04-13 20:35:52,057 WARNING FileStreamThread:28088 [file_stream.py:request_with_retry():594] requests_with_retry encountered retryable exception: HTTPSConnectionPool(host='api.wandb.ai', port=443): Max retries exceeded with url: /files/wasiim/tempo_ml_training/3rhpz40q/file_stream (Caused by NewConnectionError('<urllib3.connection.HTTPSConnection object at 0x000001F8E38245E0>: Failed to establish a new connection: [Errno 11001] getaddrinfo failed')). func: <bound method Session.post of <requests.sessions.Session object at 0x000001F8E3787310>>, args: ('https://api.wandb.ai/files/wasiim/tempo_ml_training/3rhpz40q/file_stream',), kwargs: {'json': {'complete': False, 'failed': False, 'dropped': 0, 'uploaded': []}}
2022-04-13 20:36:08,515 WARNING FileStreamThread:28088 [file_stream.py:request_with_retry():594] requests_with_retry encountered retryable exception: HTTPSConnectionPool(host='api.wandb.ai', port=443): Max retries exceeded with url: /files/wasiim/tempo_ml_training/3rhpz40q/file_stream (Caused by NewConnectionError('<urllib3.connection.HTTPSConnection object at 0x000001F8E3824070>: Failed to establish a new connection: [Errno 11001] getaddrinfo failed')). func: <bound method Session.post of <requests.sessions.Session object at 0x000001F8E3787310>>, args: ('https://api.wandb.ai/files/wasiim/tempo_ml_training/3rhpz40q/file_stream',), kwargs: {'json': {'complete': False, 'failed': False, 'dropped': 0, 'uploaded': []}}
2022-04-13 20:36:41,853 WARNING FileStreamThread:28088 [file_stream.py:request_with_retry():594] requests_with_retry encountered retryable exception: HTTPSConnectionPool(host='api.wandb.ai', port=443): Max retries exceeded with url: /files/wasiim/tempo_ml_training/3rhpz40q/file_stream (Caused by NewConnectionError('<urllib3.connection.HTTPSConnection object at 0x000001F8E38246D0>: Failed to establish a new connection: [Errno 11001] getaddrinfo failed')). func: <bound method Session.post of <requests.sessions.Session object at 0x000001F8E3787310>>, args: ('https://api.wandb.ai/files/wasiim/tempo_ml_training/3rhpz40q/file_stream',), kwargs: {'json': {'complete': False, 'failed': False, 'dropped': 0, 'uploaded': []}}
2022-04-14 01:38:28,828 WARNING FileStreamThread:28088 [file_stream.py:request_with_retry():594] requests_with_retry encountered retryable exception: ('Connection aborted.', ConnectionResetError(10054, 'An existing connection was forcibly closed by the remote host', None, 10054, None)). func: <bound method Session.post of <requests.sessions.Session object at 0x000001F8E3787310>>, args: ('https://api.wandb.ai/files/wasiim/tempo_ml_training/3rhpz40q/file_stream',), kwargs: {'json': {'complete': False, 'failed': False, 'dropped': 0, 'uploaded': []}}
2022-04-14 08:47:25,801 WARNING FileStreamThread:28088 [file_stream.py:request_with_retry():594] requests_with_retry encountered retryable exception: ('Connection aborted.', ConnectionResetError(10054, 'An existing connection was forcibly closed by the remote host', None, 10054, None)). func: <bound method Session.post of <requests.sessions.Session object at 0x000001F8E3787310>>, args: ('https://api.wandb.ai/files/wasiim/tempo_ml_training/3rhpz40q/file_stream',), kwargs: {'json': {'complete': False, 'failed': False, 'dropped': 0, 'uploaded': []}}
2022-04-14 09:49:24,500 WARNING FileStreamThread:28088 [file_stream.py:request_with_retry():594] requests_with_retry encountered retryable exception: ('Connection aborted.', TimeoutError(10060, 'A connection attempt failed because the connected party did not properly respond after a period of time, or established connection failed because connected host has failed to respond', None, 10060, None)). func: <bound method Session.post of <requests.sessions.Session object at 0x000001F8E3787310>>, args: ('https://api.wandb.ai/files/wasiim/tempo_ml_training/3rhpz40q/file_stream',), kwargs: {'json': {'complete': False, 'failed': False, 'dropped': 0, 'uploaded': []}}
2022-04-14 09:49:26,757 WARNING FileStreamThread:28088 [file_stream.py:request_with_retry():594] requests_with_retry encountered retryable exception: HTTPSConnectionPool(host='api.wandb.ai', port=443): Max retries exceeded with url: /files/wasiim/tempo_ml_training/3rhpz40q/file_stream (Caused by NewConnectionError('<urllib3.connection.HTTPSConnection object at 0x000001F8E3827C10>: Failed to establish a new connection: [Errno 11001] getaddrinfo failed')). func: <bound method Session.post of <requests.sessions.Session object at 0x000001F8E3787310>>, args: ('https://api.wandb.ai/files/wasiim/tempo_ml_training/3rhpz40q/file_stream',), kwargs: {'json': {'complete': False, 'failed': False, 'dropped': 0, 'uploaded': []}}
2022-04-14 09:49:31,571 WARNING FileStreamThread:28088 [file_stream.py:request_with_retry():594] requests_with_retry encountered retryable exception: HTTPSConnectionPool(host='api.wandb.ai', port=443): Max retries exceeded with url: /files/wasiim/tempo_ml_training/3rhpz40q/file_stream (Caused by NewConnectionError('<urllib3.connection.HTTPSConnection object at 0x000001F8E3827A60>: Failed to establish a new connection: [Errno 11001] getaddrinfo failed')). func: <bound method Session.post of <requests.sessions.Session object at 0x000001F8E3787310>>, args: ('https://api.wandb.ai/files/wasiim/tempo_ml_training/3rhpz40q/file_stream',), kwargs: {'json': {'complete': False, 'failed': False, 'dropped': 0, 'uploaded': []}}
2022-04-14 09:49:39,717 WARNING FileStreamThread:28088 [file_stream.py:request_with_retry():594] requests_with_retry encountered retryable exception: HTTPSConnectionPool(host='api.wandb.ai', port=443): Max retries exceeded with url: /files/wasiim/tempo_ml_training/3rhpz40q/file_stream (Caused by NewConnectionError('<urllib3.connection.HTTPSConnection object at 0x000001F8E38277F0>: Failed to establish a new connection: [Errno 11001] getaddrinfo failed')). func: <bound method Session.post of <requests.sessions.Session object at 0x000001F8E3787310>>, args: ('https://api.wandb.ai/files/wasiim/tempo_ml_training/3rhpz40q/file_stream',), kwargs: {'json': {'complete': False, 'failed': False, 'dropped': 0, 'uploaded': []}}
2022-04-14 09:49:58,371 WARNING FileStreamThread:28088 [file_stream.py:request_with_retry():594] requests_with_retry encountered retryable exception: HTTPSConnectionPool(host='api.wandb.ai', port=443): Max retries exceeded with url: /files/wasiim/tempo_ml_training/3rhpz40q/file_stream (Caused by NewConnectionError('<urllib3.connection.HTTPSConnection object at 0x000001F8E38278E0>: Failed to establish a new connection: [Errno 11001] getaddrinfo failed')). func: <bound method Session.post of <requests.sessions.Session object at 0x000001F8E3787310>>, args: ('https://api.wandb.ai/files/wasiim/tempo_ml_training/3rhpz40q/file_stream',), kwargs: {'json': {'complete': False, 'failed': False, 'dropped': 0, 'uploaded': []}}
2022-04-14 09:50:34,236 WARNING FileStreamThread:28088 [file_stream.py:request_with_retry():594] requests_with_retry encountered retryable exception: HTTPSConnectionPool(host='api.wandb.ai', port=443): Max retries exceeded with url: /files/wasiim/tempo_ml_training/3rhpz40q/file_stream (Caused by NewConnectionError('<urllib3.connection.HTTPSConnection object at 0x000001F8E3827700>: Failed to establish a new connection: [Errno 11001] getaddrinfo failed')). func: <bound method Session.post of <requests.sessions.Session object at 0x000001F8E3787310>>, args: ('https://api.wandb.ai/files/wasiim/tempo_ml_training/3rhpz40q/file_stream',), kwargs: {'json': {'complete': False, 'failed': False, 'dropped': 0, 'uploaded': []}}
2022-04-14 09:51:50,843 WARNING FileStreamThread:28088 [file_stream.py:request_with_retry():594] requests_with_retry encountered retryable exception: HTTPSConnectionPool(host='api.wandb.ai', port=443): Max retries exceeded with url: /files/wasiim/tempo_ml_training/3rhpz40q/file_stream (Caused by NewConnectionError('<urllib3.connection.HTTPSConnection object at 0x000001F8E3827A30>: Failed to establish a new connection: [Errno 11001] getaddrinfo failed')). func: <bound method Session.post of <requests.sessions.Session object at 0x000001F8E3787310>>, args: ('https://api.wandb.ai/files/wasiim/tempo_ml_training/3rhpz40q/file_stream',), kwargs: {'json': {'complete': False, 'failed': False, 'dropped': 0, 'uploaded': []}}
2022-04-14 09:54:03,557 WARNING FileStreamThread:28088 [file_stream.py:request_with_retry():594] requests_with_retry encountered retryable exception: HTTPSConnectionPool(host='api.wandb.ai', port=443): Max retries exceeded with url: /files/wasiim/tempo_ml_training/3rhpz40q/file_stream (Caused by NewConnectionError('<urllib3.connection.HTTPSConnection object at 0x000001F8E377A820>: Failed to establish a new connection: [Errno 11001] getaddrinfo failed')). func: <bound method Session.post of <requests.sessions.Session object at 0x000001F8E3787310>>, args: ('https://api.wandb.ai/files/wasiim/tempo_ml_training/3rhpz40q/file_stream',), kwargs: {'json': {'complete': False, 'failed': False, 'dropped': 0, 'uploaded': []}}
2022-04-14 09:58:38,479 WARNING FileStreamThread:28088 [file_stream.py:request_with_retry():594] requests_with_retry encountered retryable exception: HTTPSConnectionPool(host='api.wandb.ai', port=443): Max retries exceeded with url: /files/wasiim/tempo_ml_training/3rhpz40q/file_stream (Caused by NewConnectionError('<urllib3.connection.HTTPSConnection object at 0x000001F8E3836D60>: Failed to establish a new connection: [Errno 11001] getaddrinfo failed')). func: <bound method Session.post of <requests.sessions.Session object at 0x000001F8E3787310>>, args: ('https://api.wandb.ai/files/wasiim/tempo_ml_training/3rhpz40q/file_stream',), kwargs: {'json': {'complete': False, 'failed': False, 'dropped': 0, 'uploaded': []}}
2022-04-14 10:04:13,099 WARNING FileStreamThread:28088 [file_stream.py:request_with_retry():594] requests_with_retry encountered retryable exception: HTTPSConnectionPool(host='api.wandb.ai', port=443): Max retries exceeded with url: /files/wasiim/tempo_ml_training/3rhpz40q/file_stream (Caused by NewConnectionError('<urllib3.connection.HTTPSConnection object at 0x000001F8E3827070>: Failed to establish a new connection: [Errno 11001] getaddrinfo failed')). func: <bound method Session.post of <requests.sessions.Session object at 0x000001F8E3787310>>, args: ('https://api.wandb.ai/files/wasiim/tempo_ml_training/3rhpz40q/file_stream',), kwargs: {'json': {'complete': False, 'failed': False, 'dropped': 0, 'uploaded': []}}
2022-04-14 10:09:14,607 WARNING FileStreamThread:28088 [file_stream.py:request_with_retry():594] requests_with_retry encountered retryable exception: HTTPSConnectionPool(host='api.wandb.ai', port=443): Max retries exceeded with url: /files/wasiim/tempo_ml_training/3rhpz40q/file_stream (Caused by NewConnectionError('<urllib3.connection.HTTPSConnection object at 0x000001F8E3827F70>: Failed to establish a new connection: [Errno 11001] getaddrinfo failed')). func: <bound method Session.post of <requests.sessions.Session object at 0x000001F8E3787310>>, args: ('https://api.wandb.ai/files/wasiim/tempo_ml_training/3rhpz40q/file_stream',), kwargs: {'json': {'complete': False, 'failed': False, 'dropped': 0, 'uploaded': []}}
2022-04-14 10:34:23,878 WARNING FileStreamThread:28088 [file_stream.py:request_with_retry():594] requests_with_retry encountered retryable exception: 500 Server Error: Internal Server Error for url: https://api.wandb.ai/files/wasiim/tempo_ml_training/3rhpz40q/file_stream. func: <bound method Session.post of <requests.sessions.Session object at 0x000001F8E3787310>>, args: ('https://api.wandb.ai/files/wasiim/tempo_ml_training/3rhpz40q/file_stream',), kwargs: {'json': {'complete': False, 'failed': False, 'dropped': 0, 'uploaded': []}}
2022-04-14 10:50:47,087 WARNING FileStreamThread:28088 [file_stream.py:request_with_retry():594] requests_with_retry encountered retryable exception: ('Connection aborted.', ConnectionResetError(10054, 'An existing connection was forcibly closed by the remote host', None, 10054, None)). func: <bound method Session.post of <requests.sessions.Session object at 0x000001F8E3787310>>, args: ('https://api.wandb.ai/files/wasiim/tempo_ml_training/3rhpz40q/file_stream',), kwargs: {'json': {'complete': False, 'failed': False, 'dropped': 0, 'uploaded': []}}
2022-04-14 17:10:05,591 WARNING FileStreamThread:28088 [file_stream.py:request_with_retry():594] requests_with_retry encountered retryable exception: HTTPSConnectionPool(host='api.wandb.ai', port=443): Max retries exceeded with url: /files/wasiim/tempo_ml_training/3rhpz40q/file_stream (Caused by NewConnectionError('<urllib3.connection.HTTPSConnection object at 0x000001F8E3824F70>: Failed to establish a new connection: [Errno 11001] getaddrinfo failed')). func: <bound method Session.post of <requests.sessions.Session object at 0x000001F8E3787310>>, args: ('https://api.wandb.ai/files/wasiim/tempo_ml_training/3rhpz40q/file_stream',), kwargs: {'json': {'complete': False, 'failed': False, 'dropped': 0, 'uploaded': []}}
2022-04-14 17:10:07,897 WARNING FileStreamThread:28088 [file_stream.py:request_with_retry():594] requests_with_retry encountered retryable exception: HTTPSConnectionPool(host='api.wandb.ai', port=443): Max retries exceeded with url: /files/wasiim/tempo_ml_training/3rhpz40q/file_stream (Caused by NewConnectionError('<urllib3.connection.HTTPSConnection object at 0x000001F8E3827FD0>: Failed to establish a new connection: [Errno 11001] getaddrinfo failed')). func: <bound method Session.post of <requests.sessions.Session object at 0x000001F8E3787310>>, args: ('https://api.wandb.ai/files/wasiim/tempo_ml_training/3rhpz40q/file_stream',), kwargs: {'json': {'complete': False, 'failed': False, 'dropped': 0, 'uploaded': []}}
2022-04-14 17:10:12,705 WARNING FileStreamThread:28088 [file_stream.py:request_with_retry():594] requests_with_retry encountered retryable exception: HTTPSConnectionPool(host='api.wandb.ai', port=443): Max retries exceeded with url: /files/wasiim/tempo_ml_training/3rhpz40q/file_stream (Caused by NewConnectionError('<urllib3.connection.HTTPSConnection object at 0x000001F8E3827610>: Failed to establish a new connection: [Errno 11001] getaddrinfo failed')). func: <bound method Session.post of <requests.sessions.Session object at 0x000001F8E3787310>>, args: ('https://api.wandb.ai/files/wasiim/tempo_ml_training/3rhpz40q/file_stream',), kwargs: {'json': {'complete': False, 'failed': False, 'dropped': 0, 'uploaded': []}}
2022-04-14 17:10:22,570 WARNING FileStreamThread:28088 [file_stream.py:request_with_retry():594] requests_with_retry encountered retryable exception: HTTPSConnectionPool(host='api.wandb.ai', port=443): Max retries exceeded with url: /files/wasiim/tempo_ml_training/3rhpz40q/file_stream (Caused by NewConnectionError('<urllib3.connection.HTTPSConnection object at 0x000001F8E3827B50>: Failed to establish a new connection: [Errno 11001] getaddrinfo failed')). func: <bound method Session.post of <requests.sessions.Session object at 0x000001F8E3787310>>, args: ('https://api.wandb.ai/files/wasiim/tempo_ml_training/3rhpz40q/file_stream',), kwargs: {'json': {'complete': False, 'failed': False, 'dropped': 0, 'uploaded': []}}
2022-04-14 17:10:41,311 WARNING FileStreamThread:28088 [file_stream.py:request_with_retry():594] requests_with_retry encountered retryable exception: HTTPSConnectionPool(host='api.wandb.ai', port=443): Max retries exceeded with url: /files/wasiim/tempo_ml_training/3rhpz40q/file_stream (Caused by NewConnectionError('<urllib3.connection.HTTPSConnection object at 0x000001F8E382E3D0>: Failed to establish a new connection: [Errno 11001] getaddrinfo failed')). func: <bound method Session.post of <requests.sessions.Session object at 0x000001F8E3787310>>, args: ('https://api.wandb.ai/files/wasiim/tempo_ml_training/3rhpz40q/file_stream',), kwargs: {'json': {'complete': False, 'failed': False, 'dropped': 0, 'uploaded': []}}
2022-04-14 18:08:15,808 WARNING FileStreamThread:28088 [file_stream.py:request_with_retry():594] requests_with_retry encountered retryable exception: ('Connection aborted.', ConnectionResetError(10054, 'An existing connection was forcibly closed by the remote host', None, 10054, None)). func: <bound method Session.post of <requests.sessions.Session object at 0x000001F8E3787310>>, args: ('https://api.wandb.ai/files/wasiim/tempo_ml_training/3rhpz40q/file_stream',), kwargs: {'json': {'complete': False, 'failed': False, 'dropped': 0, 'uploaded': []}}
2022-04-14 21:19:43,371 WARNING FileStreamThread:28088 [file_stream.py:request_with_retry():594] requests_with_retry encountered retryable exception: 500 Server Error: Internal Server Error for url: https://api.wandb.ai/files/wasiim/tempo_ml_training/3rhpz40q/file_stream. func: <bound method Session.post of <requests.sessions.Session object at 0x000001F8E3787310>>, args: ('https://api.wandb.ai/files/wasiim/tempo_ml_training/3rhpz40q/file_stream',), kwargs: {'json': {'complete': False, 'failed': False, 'dropped': 0, 'uploaded': []}}
2022-04-14 21:20:02,260 WARNING FileStreamThread:28088 [file_stream.py:request_with_retry():594] requests_with_retry encountered retryable exception: 500 Server Error: Internal Server Error for url: https://api.wandb.ai/files/wasiim/tempo_ml_training/3rhpz40q/file_stream. func: <bound method Session.post of <requests.sessions.Session object at 0x000001F8E3787310>>, args: ('https://api.wandb.ai/files/wasiim/tempo_ml_training/3rhpz40q/file_stream',), kwargs: {'json': {'complete': False, 'failed': False, 'dropped': 0, 'uploaded': []}}
2022-04-14 21:20:07,147 WARNING FileStreamThread:28088 [file_stream.py:request_with_retry():594] requests_with_retry encountered retryable exception: 500 Server Error: Internal Server Error for url: https://api.wandb.ai/files/wasiim/tempo_ml_training/3rhpz40q/file_stream. func: <bound method Session.post of <requests.sessions.Session object at 0x000001F8E3787310>>, args: ('https://api.wandb.ai/files/wasiim/tempo_ml_training/3rhpz40q/file_stream',), kwargs: {'json': {'complete': False, 'failed': False, 'dropped': 0, 'uploaded': []}}
2022-04-14 21:20:17,002 WARNING FileStreamThread:28088 [file_stream.py:request_with_retry():594] requests_with_retry encountered retryable exception: 500 Server Error: Internal Server Error for url: https://api.wandb.ai/files/wasiim/tempo_ml_training/3rhpz40q/file_stream. func: <bound method Session.post of <requests.sessions.Session object at 0x000001F8E3787310>>, args: ('https://api.wandb.ai/files/wasiim/tempo_ml_training/3rhpz40q/file_stream',), kwargs: {'json': {'complete': False, 'failed': False, 'dropped': 0, 'uploaded': []}}
2022-04-14 21:20:33,260 WARNING FileStreamThread:28088 [file_stream.py:request_with_retry():594] requests_with_retry encountered retryable exception: 500 Server Error: Internal Server Error for url: https://api.wandb.ai/files/wasiim/tempo_ml_training/3rhpz40q/file_stream. func: <bound method Session.post of <requests.sessions.Session object at 0x000001F8E3787310>>, args: ('https://api.wandb.ai/files/wasiim/tempo_ml_training/3rhpz40q/file_stream',), kwargs: {'json': {'complete': False, 'failed': False, 'dropped': 0, 'uploaded': []}}
2022-04-14 21:21:10,213 WARNING FileStreamThread:28088 [file_stream.py:request_with_retry():594] requests_with_retry encountered retryable exception: 500 Server Error: Internal Server Error for url: https://api.wandb.ai/files/wasiim/tempo_ml_training/3rhpz40q/file_stream. func: <bound method Session.post of <requests.sessions.Session object at 0x000001F8E3787310>>, args: ('https://api.wandb.ai/files/wasiim/tempo_ml_training/3rhpz40q/file_stream',), kwargs: {'json': {'complete': False, 'failed': False, 'dropped': 0, 'uploaded': []}}
2022-04-14 21:22:18,187 WARNING FileStreamThread:28088 [file_stream.py:request_with_retry():594] requests_with_retry encountered retryable exception: 500 Server Error: Internal Server Error for url: https://api.wandb.ai/files/wasiim/tempo_ml_training/3rhpz40q/file_stream. func: <bound method Session.post of <requests.sessions.Session object at 0x000001F8E3787310>>, args: ('https://api.wandb.ai/files/wasiim/tempo_ml_training/3rhpz40q/file_stream',), kwargs: {'json': {'complete': False, 'failed': False, 'dropped': 0, 'uploaded': []}}
2022-04-14 21:24:44,823 WARNING FileStreamThread:28088 [file_stream.py:request_with_retry():594] requests_with_retry encountered retryable exception: ('Connection aborted.', ConnectionResetError(10054, 'An existing connection was forcibly closed by the remote host', None, 10054, None)). func: <bound method Session.post of <requests.sessions.Session object at 0x000001F8E3787310>>, args: ('https://api.wandb.ai/files/wasiim/tempo_ml_training/3rhpz40q/file_stream',), kwargs: {'json': {'complete': False, 'failed': False, 'dropped': 0, 'uploaded': []}}
2022-04-14 21:54:12,474 WARNING FileStreamThread:28088 [file_stream.py:request_with_retry():594] requests_with_retry encountered retryable exception: ('Connection aborted.', TimeoutError(10060, 'A connection attempt failed because the connected party did not properly respond after a period of time, or established connection failed because connected host has failed to respond', None, 10060, None)). func: <bound method Session.post of <requests.sessions.Session object at 0x000001F8E3787310>>, args: ('https://api.wandb.ai/files/wasiim/tempo_ml_training/3rhpz40q/file_stream',), kwargs: {'json': {'complete': False, 'failed': False, 'dropped': 0, 'uploaded': []}}
2022-04-14 21:54:14,608 WARNING FileStreamThread:28088 [file_stream.py:request_with_retry():594] requests_with_retry encountered retryable exception: HTTPSConnectionPool(host='api.wandb.ai', port=443): Max retries exceeded with url: /files/wasiim/tempo_ml_training/3rhpz40q/file_stream (Caused by NewConnectionError('<urllib3.connection.HTTPSConnection object at 0x000001F8E3812EE0>: Failed to establish a new connection: [Errno 11001] getaddrinfo failed')). func: <bound method Session.post of <requests.sessions.Session object at 0x000001F8E3787310>>, args: ('https://api.wandb.ai/files/wasiim/tempo_ml_training/3rhpz40q/file_stream',), kwargs: {'json': {'complete': False, 'failed': False, 'dropped': 0, 'uploaded': []}}
2022-04-14 21:54:18,776 WARNING FileStreamThread:28088 [file_stream.py:request_with_retry():594] requests_with_retry encountered retryable exception: HTTPSConnectionPool(host='api.wandb.ai', port=443): Max retries exceeded with url: /files/wasiim/tempo_ml_training/3rhpz40q/file_stream (Caused by NewConnectionError('<urllib3.connection.HTTPSConnection object at 0x000001F8E382ED30>: Failed to establish a new connection: [Errno 11001] getaddrinfo failed')). func: <bound method Session.post of <requests.sessions.Session object at 0x000001F8E3787310>>, args: ('https://api.wandb.ai/files/wasiim/tempo_ml_training/3rhpz40q/file_stream',), kwargs: {'json': {'complete': False, 'failed': False, 'dropped': 0, 'uploaded': []}}
2022-04-14 21:54:27,476 WARNING FileStreamThread:28088 [file_stream.py:request_with_retry():594] requests_with_retry encountered retryable exception: HTTPSConnectionPool(host='api.wandb.ai', port=443): Max retries exceeded with url: /files/wasiim/tempo_ml_training/3rhpz40q/file_stream (Caused by NewConnectionError('<urllib3.connection.HTTPSConnection object at 0x000001F8E382E610>: Failed to establish a new connection: [Errno 11001] getaddrinfo failed')). func: <bound method Session.post of <requests.sessions.Session object at 0x000001F8E3787310>>, args: ('https://api.wandb.ai/files/wasiim/tempo_ml_training/3rhpz40q/file_stream',), kwargs: {'json': {'complete': False, 'failed': False, 'dropped': 0, 'uploaded': []}}
2022-04-14 21:54:44,315 WARNING FileStreamThread:28088 [file_stream.py:request_with_retry():594] requests_with_retry encountered retryable exception: HTTPSConnectionPool(host='api.wandb.ai', port=443): Max retries exceeded with url: /files/wasiim/tempo_ml_training/3rhpz40q/file_stream (Caused by NewConnectionError('<urllib3.connection.HTTPSConnection object at 0x000001F8E382ED30>: Failed to establish a new connection: [Errno 11001] getaddrinfo failed')). func: <bound method Session.post of <requests.sessions.Session object at 0x000001F8E3787310>>, args: ('https://api.wandb.ai/files/wasiim/tempo_ml_training/3rhpz40q/file_stream',), kwargs: {'json': {'complete': False, 'failed': False, 'dropped': 0, 'uploaded': []}}
2022-04-14 21:55:18,516 WARNING FileStreamThread:28088 [file_stream.py:request_with_retry():594] requests_with_retry encountered retryable exception: HTTPSConnectionPool(host='api.wandb.ai', port=443): Max retries exceeded with url: /files/wasiim/tempo_ml_training/3rhpz40q/file_stream (Caused by NewConnectionError('<urllib3.connection.HTTPSConnection object at 0x000001F8E382E430>: Failed to establish a new connection: [Errno 11001] getaddrinfo failed')). func: <bound method Session.post of <requests.sessions.Session object at 0x000001F8E3787310>>, args: ('https://api.wandb.ai/files/wasiim/tempo_ml_training/3rhpz40q/file_stream',), kwargs: {'json': {'complete': False, 'failed': False, 'dropped': 0, 'uploaded': []}}
2022-04-14 23:47:13,705 WARNING FileStreamThread:28088 [file_stream.py:request_with_retry():594] requests_with_retry encountered retryable exception: 500 Server Error: Internal Server Error for url: https://api.wandb.ai/files/wasiim/tempo_ml_training/3rhpz40q/file_stream. func: <bound method Session.post of <requests.sessions.Session object at 0x000001F8E3787310>>, args: ('https://api.wandb.ai/files/wasiim/tempo_ml_training/3rhpz40q/file_stream',), kwargs: {'json': {'complete': False, 'failed': False, 'dropped': 0, 'uploaded': []}}
2022-04-15 00:52:03,364 WARNING FileStreamThread:28088 [file_stream.py:request_with_retry():594] requests_with_retry encountered retryable exception: ('Connection aborted.', TimeoutError(10060, 'A connection attempt failed because the connected party did not properly respond after a period of time, or established connection failed because connected host has failed to respond', None, 10060, None)). func: <bound method Session.post of <requests.sessions.Session object at 0x000001F8E3787310>>, args: ('https://api.wandb.ai/files/wasiim/tempo_ml_training/3rhpz40q/file_stream',), kwargs: {'json': {'complete': False, 'failed': False, 'dropped': 0, 'uploaded': []}}
2022-04-15 00:52:16,631 WARNING FileStreamThread:28088 [file_stream.py:request_with_retry():594] requests_with_retry encountered retryable exception: HTTPSConnectionPool(host='api.wandb.ai', port=443): Max retries exceeded with url: /files/wasiim/tempo_ml_training/3rhpz40q/file_stream (Caused by NewConnectionError('<urllib3.connection.HTTPSConnection object at 0x000001F8E3824070>: Failed to establish a new connection: [Errno 11001] getaddrinfo failed')). func: <bound method Session.post of <requests.sessions.Session object at 0x000001F8E3787310>>, args: ('https://api.wandb.ai/files/wasiim/tempo_ml_training/3rhpz40q/file_stream',), kwargs: {'json': {'complete': False, 'failed': False, 'dropped': 0, 'uploaded': []}}
2022-04-15 00:52:20,715 WARNING FileStreamThread:28088 [file_stream.py:request_with_retry():594] requests_with_retry encountered retryable exception: HTTPSConnectionPool(host='api.wandb.ai', port=443): Max retries exceeded with url: /files/wasiim/tempo_ml_training/3rhpz40q/file_stream (Caused by NewConnectionError('<urllib3.connection.HTTPSConnection object at 0x000001F8E38244F0>: Failed to establish a new connection: [Errno 11001] getaddrinfo failed')). func: <bound method Session.post of <requests.sessions.Session object at 0x000001F8E3787310>>, args: ('https://api.wandb.ai/files/wasiim/tempo_ml_training/3rhpz40q/file_stream',), kwargs: {'json': {'complete': False, 'failed': False, 'dropped': 0, 'uploaded': []}}
2022-04-15 00:52:30,042 WARNING FileStreamThread:28088 [file_stream.py:request_with_retry():594] requests_with_retry encountered retryable exception: HTTPSConnectionPool(host='api.wandb.ai', port=443): Max retries exceeded with url: /files/wasiim/tempo_ml_training/3rhpz40q/file_stream (Caused by NewConnectionError('<urllib3.connection.HTTPSConnection object at 0x000001F8E3824760>: Failed to establish a new connection: [Errno 11001] getaddrinfo failed')). func: <bound method Session.post of <requests.sessions.Session object at 0x000001F8E3787310>>, args: ('https://api.wandb.ai/files/wasiim/tempo_ml_training/3rhpz40q/file_stream',), kwargs: {'json': {'complete': False, 'failed': False, 'dropped': 0, 'uploaded': []}}
2022-04-15 00:52:58,495 WARNING FileStreamThread:28088 [file_stream.py:request_with_retry():594] requests_with_retry encountered retryable exception: HTTPSConnectionPool(host='api.wandb.ai', port=443): Max retries exceeded with url: /files/wasiim/tempo_ml_training/3rhpz40q/file_stream (Caused by NewConnectionError('<urllib3.connection.HTTPSConnection object at 0x000001F8E38378B0>: Failed to establish a new connection: [Errno 11001] getaddrinfo failed')). func: <bound method Session.post of <requests.sessions.Session object at 0x000001F8E3787310>>, args: ('https://api.wandb.ai/files/wasiim/tempo_ml_training/3rhpz40q/file_stream',), kwargs: {'json': {'complete': False, 'failed': False, 'dropped': 0, 'uploaded': []}}
2022-04-15 00:53:30,891 WARNING FileStreamThread:28088 [file_stream.py:request_with_retry():594] requests_with_retry encountered retryable exception: HTTPSConnectionPool(host='api.wandb.ai', port=443): Max retries exceeded with url: /files/wasiim/tempo_ml_training/3rhpz40q/file_stream (Caused by NewConnectionError('<urllib3.connection.HTTPSConnection object at 0x000001F8E3837F10>: Failed to establish a new connection: [Errno 11001] getaddrinfo failed')). func: <bound method Session.post of <requests.sessions.Session object at 0x000001F8E3787310>>, args: ('https://api.wandb.ai/files/wasiim/tempo_ml_training/3rhpz40q/file_stream',), kwargs: {'json': {'complete': False, 'failed': False, 'dropped': 0, 'uploaded': []}}
2022-04-15 03:08:49,317 WARNING FileStreamThread:28088 [file_stream.py:request_with_retry():594] requests_with_retry encountered retryable exception: ('Connection aborted.', ConnectionResetError(10054, 'An existing connection was forcibly closed by the remote host', None, 10054, None)). func: <bound method Session.post of <requests.sessions.Session object at 0x000001F8E3787310>>, args: ('https://api.wandb.ai/files/wasiim/tempo_ml_training/3rhpz40q/file_stream',), kwargs: {'json': {'complete': False, 'failed': False, 'dropped': 0, 'uploaded': []}}
2022-04-15 13:13:44,573 WARNING FileStreamThread:28088 [file_stream.py:request_with_retry():594] requests_with_retry encountered retryable exception: ('Connection aborted.', ConnectionResetError(10054, 'An existing connection was forcibly closed by the remote host', None, 10054, None)). func: <bound method Session.post of <requests.sessions.Session object at 0x000001F8E3787310>>, args: ('https://api.wandb.ai/files/wasiim/tempo_ml_training/3rhpz40q/file_stream',), kwargs: {'json': {'complete': False, 'failed': False, 'dropped': 0, 'uploaded': []}}
2022-04-15 20:36:24,929 WARNING FileStreamThread:28088 [file_stream.py:request_with_retry():594] requests_with_retry encountered retryable exception: ('Connection aborted.', TimeoutError(10060, 'A connection attempt failed because the connected party did not properly respond after a period of time, or established connection failed because connected host has failed to respond', None, 10060, None)). func: <bound method Session.post of <requests.sessions.Session object at 0x000001F8E3787310>>, args: ('https://api.wandb.ai/files/wasiim/tempo_ml_training/3rhpz40q/file_stream',), kwargs: {'json': {'complete': False, 'failed': False, 'dropped': 0, 'uploaded': []}}
2022-04-15 20:36:27,026 WARNING FileStreamThread:28088 [file_stream.py:request_with_retry():594] requests_with_retry encountered retryable exception: HTTPSConnectionPool(host='api.wandb.ai', port=443): Max retries exceeded with url: /files/wasiim/tempo_ml_training/3rhpz40q/file_stream (Caused by NewConnectionError('<urllib3.connection.HTTPSConnection object at 0x000001F8E3837640>: Failed to establish a new connection: [Errno 11001] getaddrinfo failed')). func: <bound method Session.post of <requests.sessions.Session object at 0x000001F8E3787310>>, args: ('https://api.wandb.ai/files/wasiim/tempo_ml_training/3rhpz40q/file_stream',), kwargs: {'json': {'complete': False, 'failed': False, 'dropped': 0, 'uploaded': []}}
2022-04-15 20:36:31,610 WARNING FileStreamThread:28088 [file_stream.py:request_with_retry():594] requests_with_retry encountered retryable exception: HTTPSConnectionPool(host='api.wandb.ai', port=443): Max retries exceeded with url: /files/wasiim/tempo_ml_training/3rhpz40q/file_stream (Caused by NewConnectionError('<urllib3.connection.HTTPSConnection object at 0x000001F8E3837490>: Failed to establish a new connection: [Errno 11001] getaddrinfo failed')). func: <bound method Session.post of <requests.sessions.Session object at 0x000001F8E3787310>>, args: ('https://api.wandb.ai/files/wasiim/tempo_ml_training/3rhpz40q/file_stream',), kwargs: {'json': {'complete': False, 'failed': False, 'dropped': 0, 'uploaded': []}}
2022-04-15 20:36:42,662 WARNING FileStreamThread:28088 [file_stream.py:request_with_retry():594] requests_with_retry encountered retryable exception: HTTPSConnectionPool(host='api.wandb.ai', port=443): Max retries exceeded with url: /files/wasiim/tempo_ml_training/3rhpz40q/file_stream (Caused by NewConnectionError('<urllib3.connection.HTTPSConnection object at 0x000001F8E3837D60>: Failed to establish a new connection: [Errno 11001] getaddrinfo failed')). func: <bound method Session.post of <requests.sessions.Session object at 0x000001F8E3787310>>, args: ('https://api.wandb.ai/files/wasiim/tempo_ml_training/3rhpz40q/file_stream',), kwargs: {'json': {'complete': False, 'failed': False, 'dropped': 0, 'uploaded': []}}
2022-04-15 20:37:13,716 WARNING FileStreamThread:28088 [file_stream.py:request_with_retry():594] requests_with_retry encountered retryable exception: HTTPSConnectionPool(host='api.wandb.ai', port=443): Max retries exceeded with url: /files/wasiim/tempo_ml_training/3rhpz40q/file_stream (Caused by NewConnectionError('<urllib3.connection.HTTPSConnection object at 0x000001F8E3837E80>: Failed to establish a new connection: [Errno 11001] getaddrinfo failed')). func: <bound method Session.post of <requests.sessions.Session object at 0x000001F8E3787310>>, args: ('https://api.wandb.ai/files/wasiim/tempo_ml_training/3rhpz40q/file_stream',), kwargs: {'json': {'complete': False, 'failed': False, 'dropped': 0, 'uploaded': []}}
2022-04-15 20:37:46,554 WARNING FileStreamThread:28088 [file_stream.py:request_with_retry():594] requests_with_retry encountered retryable exception: HTTPSConnectionPool(host='api.wandb.ai', port=443): Max retries exceeded with url: /files/wasiim/tempo_ml_training/3rhpz40q/file_stream (Caused by NewConnectionError('<urllib3.connection.HTTPSConnection object at 0x000001F8E38278E0>: Failed to establish a new connection: [Errno 11001] getaddrinfo failed')). func: <bound method Session.post of <requests.sessions.Session object at 0x000001F8E3787310>>, args: ('https://api.wandb.ai/files/wasiim/tempo_ml_training/3rhpz40q/file_stream',), kwargs: {'json': {'complete': False, 'failed': False, 'dropped': 0, 'uploaded': []}}
2022-04-15 20:38:57,970 WARNING FileStreamThread:28088 [file_stream.py:request_with_retry():594] requests_with_retry encountered retryable exception: HTTPSConnectionPool(host='api.wandb.ai', port=443): Max retries exceeded with url: /files/wasiim/tempo_ml_training/3rhpz40q/file_stream (Caused by NewConnectionError('<urllib3.connection.HTTPSConnection object at 0x000001F8E3827700>: Failed to establish a new connection: [Errno 11001] getaddrinfo failed')). func: <bound method Session.post of <requests.sessions.Session object at 0x000001F8E3787310>>, args: ('https://api.wandb.ai/files/wasiim/tempo_ml_training/3rhpz40q/file_stream',), kwargs: {'json': {'complete': False, 'failed': False, 'dropped': 0, 'uploaded': []}}
2022-04-15 20:41:22,975 WARNING FileStreamThread:28088 [file_stream.py:request_with_retry():594] requests_with_retry encountered retryable exception: HTTPSConnectionPool(host='api.wandb.ai', port=443): Max retries exceeded with url: /files/wasiim/tempo_ml_training/3rhpz40q/file_stream (Caused by NewConnectionError('<urllib3.connection.HTTPSConnection object at 0x000001F8E382B370>: Failed to establish a new connection: [Errno 11001] getaddrinfo failed')). func: <bound method Session.post of <requests.sessions.Session object at 0x000001F8E3787310>>, args: ('https://api.wandb.ai/files/wasiim/tempo_ml_training/3rhpz40q/file_stream',), kwargs: {'json': {'complete': False, 'failed': False, 'dropped': 0, 'uploaded': []}}
2022-04-16 00:37:02,085 WARNING FileStreamThread:28088 [file_stream.py:request_with_retry():594] requests_with_retry encountered retryable exception: ('Connection aborted.', TimeoutError(10060, 'A connection attempt failed because the connected party did not properly respond after a period of time, or established connection failed because connected host has failed to respond', None, 10060, None)). func: <bound method Session.post of <requests.sessions.Session object at 0x000001F8E3787310>>, args: ('https://api.wandb.ai/files/wasiim/tempo_ml_training/3rhpz40q/file_stream',), kwargs: {'json': {'complete': False, 'failed': False, 'dropped': 0, 'uploaded': []}}
2022-04-16 00:37:15,389 WARNING FileStreamThread:28088 [file_stream.py:request_with_retry():594] requests_with_retry encountered retryable exception: HTTPSConnectionPool(host='api.wandb.ai', port=443): Max retries exceeded with url: /files/wasiim/tempo_ml_training/3rhpz40q/file_stream (Caused by NewConnectionError('<urllib3.connection.HTTPSConnection object at 0x000001F8E382B520>: Failed to establish a new connection: [Errno 11001] getaddrinfo failed')). func: <bound method Session.post of <requests.sessions.Session object at 0x000001F8E3787310>>, args: ('https://api.wandb.ai/files/wasiim/tempo_ml_training/3rhpz40q/file_stream',), kwargs: {'json': {'complete': False, 'failed': False, 'dropped': 0, 'uploaded': []}}
2022-04-16 00:37:30,567 WARNING FileStreamThread:28088 [file_stream.py:request_with_retry():594] requests_with_retry encountered retryable exception: HTTPSConnectionPool(host='api.wandb.ai', port=443): Max retries exceeded with url: /files/wasiim/tempo_ml_training/3rhpz40q/file_stream (Caused by NewConnectionError('<urllib3.connection.HTTPSConnection object at 0x000001F8E382BF10>: Failed to establish a new connection: [Errno 11001] getaddrinfo failed')). func: <bound method Session.post of <requests.sessions.Session object at 0x000001F8E3787310>>, args: ('https://api.wandb.ai/files/wasiim/tempo_ml_training/3rhpz40q/file_stream',), kwargs: {'json': {'complete': False, 'failed': False, 'dropped': 0, 'uploaded': []}}
2022-04-16 00:37:39,207 WARNING FileStreamThread:28088 [file_stream.py:request_with_retry():594] requests_with_retry encountered retryable exception: HTTPSConnectionPool(host='api.wandb.ai', port=443): Max retries exceeded with url: /files/wasiim/tempo_ml_training/3rhpz40q/file_stream (Caused by NewConnectionError('<urllib3.connection.HTTPSConnection object at 0x000001F8E382B820>: Failed to establish a new connection: [Errno 11001] getaddrinfo failed')). func: <bound method Session.post of <requests.sessions.Session object at 0x000001F8E3787310>>, args: ('https://api.wandb.ai/files/wasiim/tempo_ml_training/3rhpz40q/file_stream',), kwargs: {'json': {'complete': False, 'failed': False, 'dropped': 0, 'uploaded': []}}
2022-04-16 00:38:08,474 WARNING FileStreamThread:28088 [file_stream.py:request_with_retry():594] requests_with_retry encountered retryable exception: HTTPSConnectionPool(host='api.wandb.ai', port=443): Max retries exceeded with url: /files/wasiim/tempo_ml_training/3rhpz40q/file_stream (Caused by NewConnectionError('<urllib3.connection.HTTPSConnection object at 0x000001F8E382B490>: Failed to establish a new connection: [Errno 11001] getaddrinfo failed')). func: <bound method Session.post of <requests.sessions.Session object at 0x000001F8E3787310>>, args: ('https://api.wandb.ai/files/wasiim/tempo_ml_training/3rhpz40q/file_stream',), kwargs: {'json': {'complete': False, 'failed': False, 'dropped': 0, 'uploaded': []}}
2022-04-16 00:38:40,912 WARNING FileStreamThread:28088 [file_stream.py:request_with_retry():594] requests_with_retry encountered retryable exception: HTTPSConnectionPool(host='api.wandb.ai', port=443): Max retries exceeded with url: /files/wasiim/tempo_ml_training/3rhpz40q/file_stream (Caused by NewConnectionError('<urllib3.connection.HTTPSConnection object at 0x000001F8E382B5E0>: Failed to establish a new connection: [Errno 11001] getaddrinfo failed')). func: <bound method Session.post of <requests.sessions.Session object at 0x000001F8E3787310>>, args: ('https://api.wandb.ai/files/wasiim/tempo_ml_training/3rhpz40q/file_stream',), kwargs: {'json': {'complete': False, 'failed': False, 'dropped': 0, 'uploaded': []}}
2022-04-16 00:39:51,245 WARNING FileStreamThread:28088 [file_stream.py:request_with_retry():594] requests_with_retry encountered retryable exception: HTTPSConnectionPool(host='api.wandb.ai', port=443): Max retries exceeded with url: /files/wasiim/tempo_ml_training/3rhpz40q/file_stream (Caused by NewConnectionError('<urllib3.connection.HTTPSConnection object at 0x000001F8E382E970>: Failed to establish a new connection: [Errno 11001] getaddrinfo failed')). func: <bound method Session.post of <requests.sessions.Session object at 0x000001F8E3787310>>, args: ('https://api.wandb.ai/files/wasiim/tempo_ml_training/3rhpz40q/file_stream',), kwargs: {'json': {'complete': False, 'failed': False, 'dropped': 0, 'uploaded': []}}
2022-04-16 00:42:18,205 WARNING FileStreamThread:28088 [file_stream.py:request_with_retry():594] requests_with_retry encountered retryable exception: HTTPSConnectionPool(host='api.wandb.ai', port=443): Max retries exceeded with url: /files/wasiim/tempo_ml_training/3rhpz40q/file_stream (Caused by NewConnectionError('<urllib3.connection.HTTPSConnection object at 0x000001F8E3812BB0>: Failed to establish a new connection: [Errno 11001] getaddrinfo failed')). func: <bound method Session.post of <requests.sessions.Session object at 0x000001F8E3787310>>, args: ('https://api.wandb.ai/files/wasiim/tempo_ml_training/3rhpz40q/file_stream',), kwargs: {'json': {'complete': False, 'failed': False, 'dropped': 0, 'uploaded': []}}
2022-04-16 03:06:36,256 WARNING FileStreamThread:28088 [file_stream.py:request_with_retry():594] requests_with_retry encountered retryable exception: ('Connection aborted.', ConnectionResetError(10054, 'An existing connection was forcibly closed by the remote host', None, 10054, None)). func: <bound method Session.post of <requests.sessions.Session object at 0x000001F8E3787310>>, args: ('https://api.wandb.ai/files/wasiim/tempo_ml_training/3rhpz40q/file_stream',), kwargs: {'json': {'complete': False, 'failed': False, 'dropped': 0, 'uploaded': []}}
2022-04-16 03:22:33,694 WARNING FileStreamThread:28088 [file_stream.py:request_with_retry():594] requests_with_retry encountered retryable exception: ('Connection aborted.', ConnectionResetError(10054, 'An existing connection was forcibly closed by the remote host', None, 10054, None)). func: <bound method Session.post of <requests.sessions.Session object at 0x000001F8E3787310>>, args: ('https://api.wandb.ai/files/wasiim/tempo_ml_training/3rhpz40q/file_stream',), kwargs: {'json': {'complete': False, 'failed': False, 'dropped': 0, 'uploaded': []}}
2022-04-16 03:25:02,969 WARNING FileStreamThread:28088 [file_stream.py:request_with_retry():594] requests_with_retry encountered retryable exception: ('Connection aborted.', ConnectionResetError(10054, 'An existing connection was forcibly closed by the remote host', None, 10054, None)). func: <bound method Session.post of <requests.sessions.Session object at 0x000001F8E3787310>>, args: ('https://api.wandb.ai/files/wasiim/tempo_ml_training/3rhpz40q/file_stream',), kwargs: {'json': {'complete': False, 'failed': False, 'dropped': 0, 'uploaded': []}}
2022-04-16 11:37:00,828 WARNING FileStreamThread:28088 [file_stream.py:request_with_retry():594] requests_with_retry encountered retryable exception: ('Connection aborted.', ConnectionResetError(10054, 'An existing connection was forcibly closed by the remote host', None, 10054, None)). func: <bound method Session.post of <requests.sessions.Session object at 0x000001F8E3787310>>, args: ('https://api.wandb.ai/files/wasiim/tempo_ml_training/3rhpz40q/file_stream',), kwargs: {'json': {'complete': False, 'failed': False, 'dropped': 0, 'uploaded': []}}
2022-04-16 11:58:39,736 WARNING FileStreamThread:28088 [file_stream.py:request_with_retry():594] requests_with_retry encountered retryable exception: ('Connection aborted.', ConnectionResetError(10054, 'An existing connection was forcibly closed by the remote host', None, 10054, None)). func: <bound method Session.post of <requests.sessions.Session object at 0x000001F8E3787310>>, args: ('https://api.wandb.ai/files/wasiim/tempo_ml_training/3rhpz40q/file_stream',), kwargs: {'json': {'complete': False, 'failed': False, 'dropped': 0, 'uploaded': []}}
2022-04-16 12:52:13,407 WARNING MainThread:28088 [internal.py:is_dead():387] Internal process exiting, parent pid 10056 disappeared
2022-04-16 12:52:13,412 ERROR   MainThread:28088 [internal.py:wandb_internal():151] Internal process shutdown.
2022-04-16 12:52:13,736 INFO    HandlerThread:28088 [handler.py:finish():790] shutting down handler
2022-04-16 12:52:13,867 INFO    SenderThread:28088 [sender.py:finish():1107] shutting down sender
2022-04-16 12:52:13,867 INFO    SenderThread:28088 [dir_watcher.py:finish():283] shutting down directory watcher
2022-04-16 12:52:14,205 INFO    WriterThread:28088 [datastore.py:close():281] close: c:\Users\wasii\Documents\CodingProjects\TEMPO_Work\wandb\run-20220406_200902-3rhpz40q\run-3rhpz40q.wandb
2022-04-16 12:52:14,419 INFO    SenderThread:28088 [dir_watcher.py:finish():313] scan: c:\Users\wasii\Documents\CodingProjects\TEMPO_Work\wandb\run-20220406_200902-3rhpz40q\files
2022-04-16 12:52:14,426 INFO    SenderThread:28088 [dir_watcher.py:finish():327] scan save: c:\Users\wasii\Documents\CodingProjects\TEMPO_Work\wandb\run-20220406_200902-3rhpz40q\files\config.yaml config.yaml
2022-04-16 12:52:14,426 INFO    SenderThread:28088 [file_pusher.py:finish():145] shutting down file pusher
2022-04-16 12:52:14,426 INFO    SenderThread:28088 [file_pusher.py:join():150] waiting for file pusher
2022-04-16 12:52:15,576 INFO    Thread-13 :28088 [upload_job.py:push():137] Uploaded file c:\Users\wasii\Documents\CodingProjects\TEMPO_Work\wandb\run-20220406_200902-3rhpz40q\files\config.yaml
2022-04-16 12:52:16,124 INFO    MainThread:28088 [internal.py:handle_exit():82] Internal process exited
